[2022-11-23T01:17:45.463+0000] {taskinstance.py:1165} INFO - Dependencies all met for <TaskInstance: PG_to_S3.PG_to_S3 scheduled__2022-11-22T00:00:00+00:00 [queued]>
[2022-11-23T01:17:45.506+0000] {taskinstance.py:1165} INFO - Dependencies all met for <TaskInstance: PG_to_S3.PG_to_S3 scheduled__2022-11-22T00:00:00+00:00 [queued]>
[2022-11-23T01:17:45.510+0000] {taskinstance.py:1362} INFO - 
--------------------------------------------------------------------------------
[2022-11-23T01:17:45.514+0000] {taskinstance.py:1363} INFO - Starting attempt 1 of 1
[2022-11-23T01:17:45.518+0000] {taskinstance.py:1364} INFO - 
--------------------------------------------------------------------------------
[2022-11-23T01:17:45.555+0000] {taskinstance.py:1383} INFO - Executing <Task(PostgresToS3Operator): PG_to_S3> on 2022-11-22 00:00:00+00:00
[2022-11-23T01:17:45.572+0000] {standard_task_runner.py:55} INFO - Started process 38077 to run task
[2022-11-23T01:17:45.605+0000] {standard_task_runner.py:82} INFO - Running: ['***', 'tasks', 'run', 'PG_to_S3', 'PG_to_S3', 'scheduled__2022-11-22T00:00:00+00:00', '--job-id', '221', '--raw', '--subdir', 'DAGS_FOLDER/PGtoS3.py', '--cfg-path', '/tmp/tmp7ytn5hv9']
[2022-11-23T01:17:45.615+0000] {standard_task_runner.py:83} INFO - Job 221: Subtask PG_to_S3
[2022-11-23T01:17:45.845+0000] {task_command.py:376} INFO - Running <TaskInstance: PG_to_S3.PG_to_S3 scheduled__2022-11-22T00:00:00+00:00 [running]> on host b785e9657fa7
[2022-11-23T01:17:45.990+0000] {taskinstance.py:1592} INFO - Exporting the following env vars:
AIRFLOW_CTX_DAG_OWNER=eugeny
AIRFLOW_CTX_DAG_ID=PG_to_S3
AIRFLOW_CTX_TASK_ID=PG_to_S3
AIRFLOW_CTX_EXECUTION_DATE=2022-11-22T00:00:00+00:00
AIRFLOW_CTX_TRY_NUMBER=1
AIRFLOW_CTX_DAG_RUN_ID=scheduled__2022-11-22T00:00:00+00:00
[2022-11-23T01:17:56.850+0000] {taskinstance.py:1851} ERROR - Task failed with exception
Traceback (most recent call last):
  File "/opt/airflow/plugins/operators/pgtos3.py", line 30, in execute
    self.s3()
  File "/opt/airflow/plugins/operators/pgtos3.py", line 55, in s3
    data = self.postgres()
  File "/opt/airflow/plugins/operators/pgtos3.py", line 39, in postgres
    cursor.execute(self.sql)
psycopg2.OperationalError: SSL SYSCALL error: EOF detected

[2022-11-23T01:17:56.894+0000] {taskinstance.py:1406} INFO - Marking task as FAILED. dag_id=PG_to_S3, task_id=PG_to_S3, execution_date=20221122T000000, start_date=20221123T011745, end_date=20221123T011756
[2022-11-23T01:17:56.920+0000] {standard_task_runner.py:105} ERROR - Failed to execute job 221 for task PG_to_S3 (SSL SYSCALL error: EOF detected
; 38077)
[2022-11-23T01:17:57.042+0000] {local_task_job.py:164} INFO - Task exited with return code 1
[2022-11-23T01:17:57.067+0000] {local_task_job.py:273} INFO - 0 downstream tasks scheduled from follow-on schedule check
