[2022-11-30T14:01:25.260+0000] {taskinstance.py:1165} INFO - Dependencies all met for <TaskInstance: clean_trash_bucket.clean_bucket scheduled__2022-11-30T13:00:00+00:00 [queued]>
[2022-11-30T14:01:25.267+0000] {taskinstance.py:1165} INFO - Dependencies all met for <TaskInstance: clean_trash_bucket.clean_bucket scheduled__2022-11-30T13:00:00+00:00 [queued]>
[2022-11-30T14:01:25.269+0000] {taskinstance.py:1362} INFO - 
--------------------------------------------------------------------------------
[2022-11-30T14:01:25.269+0000] {taskinstance.py:1363} INFO - Starting attempt 2 of 6
[2022-11-30T14:01:25.270+0000] {taskinstance.py:1364} INFO - 
--------------------------------------------------------------------------------
[2022-11-30T14:01:25.281+0000] {taskinstance.py:1383} INFO - Executing <Task(PythonOperator): clean_bucket> on 2022-11-30 13:00:00+00:00
[2022-11-30T14:01:25.286+0000] {standard_task_runner.py:55} INFO - Started process 668 to run task
[2022-11-30T14:01:25.291+0000] {standard_task_runner.py:82} INFO - Running: ['***', 'tasks', 'run', 'clean_trash_bucket', 'clean_bucket', 'scheduled__2022-11-30T13:00:00+00:00', '--job-id', '5', '--raw', '--subdir', 'DAGS_FOLDER/CleanTrashBucket.py', '--cfg-path', '/tmp/tmpmvfvzukk']
[2022-11-30T14:01:25.294+0000] {standard_task_runner.py:83} INFO - Job 5: Subtask clean_bucket
[2022-11-30T14:01:25.357+0000] {task_command.py:376} INFO - Running <TaskInstance: clean_trash_bucket.clean_bucket scheduled__2022-11-30T13:00:00+00:00 [running]> on host cad2b5b69ef8
[2022-11-30T14:01:25.412+0000] {taskinstance.py:1592} INFO - Exporting the following env vars:
AIRFLOW_CTX_DAG_EMAIL=***.golovanov@gmail.com
AIRFLOW_CTX_DAG_OWNER=Eugeny Golovanov
AIRFLOW_CTX_DAG_ID=clean_trash_bucket
AIRFLOW_CTX_TASK_ID=clean_bucket
AIRFLOW_CTX_EXECUTION_DATE=2022-11-30T13:00:00+00:00
AIRFLOW_CTX_TRY_NUMBER=2
AIRFLOW_CTX_DAG_RUN_ID=scheduled__2022-11-30T13:00:00+00:00
[2022-11-30T14:01:25.415+0000] {taskinstance.py:1851} ERROR - Task failed with exception
Traceback (most recent call last):
  File "/home/airflow/.local/lib/python3.7/site-packages/airflow/operators/python.py", line 175, in execute
    return_value = self.execute_callable()
  File "/home/airflow/.local/lib/python3.7/site-packages/airflow/operators/python.py", line 193, in execute_callable
    return self.python_callable(*self.op_args, **self.op_kwargs)
  File "/opt/airflow/dags/CleanTrashBucket.py", line 27, in clean_bucket
    os.chdir('/Users/eugenygolovanov/Library/Mobile Documents/com~apple~CloudDocs/.Trash')
FileNotFoundError: [Errno 2] No such file or directory: '/Users/eugenygolovanov/Library/Mobile Documents/com~apple~CloudDocs/.Trash'
[2022-11-30T14:01:25.428+0000] {taskinstance.py:1406} INFO - Marking task as UP_FOR_RETRY. dag_id=clean_trash_bucket, task_id=clean_bucket, execution_date=20221130T130000, start_date=20221130T140125, end_date=20221130T140125
[2022-11-30T14:01:25.438+0000] {standard_task_runner.py:105} ERROR - Failed to execute job 5 for task clean_bucket ([Errno 2] No such file or directory: '/Users/eugenygolovanov/Library/Mobile Documents/com~apple~CloudDocs/.Trash'; 668)
[2022-11-30T14:01:25.464+0000] {local_task_job.py:164} INFO - Task exited with return code 1
[2022-11-30T14:01:25.481+0000] {local_task_job.py:273} INFO - 0 downstream tasks scheduled from follow-on schedule check
