[2022-11-07T00:31:21.385+0000] {processor.py:154} INFO - Started process (PID=52162) to work on /opt/airflow/dags/third_dug.py
[2022-11-07T00:31:21.391+0000] {processor.py:756} INFO - Processing file /opt/airflow/dags/third_dug.py for tasks to queue
[2022-11-07T00:31:21.404+0000] {logging_mixin.py:120} INFO - [2022-11-07T00:31:21.404+0000] {dagbag.py:537} INFO - Filling up the DagBag from /opt/airflow/dags/third_dug.py
[2022-11-07T00:31:23.148+0000] {logging_mixin.py:120} INFO - [2022-11-07T00:31:23.133+0000] {dagbag.py:342} ERROR - Failed to import: /opt/airflow/dags/third_dug.py
Traceback (most recent call last):
  File "/home/airflow/.local/lib/python3.7/site-packages/redis/connection.py", line 559, in connect
    sock = self._connect()
  File "/home/airflow/.local/lib/python3.7/site-packages/redis/connection.py", line 615, in _connect
    raise err
  File "/home/airflow/.local/lib/python3.7/site-packages/redis/connection.py", line 603, in _connect
    sock.connect(socket_address)
OSError: [Errno 99] Cannot assign requested address

During handling of the above exception, another exception occurred:

Traceback (most recent call last):
  File "/home/airflow/.local/lib/python3.7/site-packages/airflow/models/dagbag.py", line 338, in parse
    loader.exec_module(new_module)
  File "<frozen importlib._bootstrap_external>", line 728, in exec_module
  File "<frozen importlib._bootstrap>", line 219, in _call_with_frames_removed
  File "/opt/airflow/dags/third_dug.py", line 74, in <module>
    python_callable=table_1_columns()
  File "/opt/airflow/dags/third_dug.py", line 63, in table_1_columns
    blob = r.get('table_1')
  File "/home/airflow/.local/lib/python3.7/site-packages/redis/client.py", line 1606, in get
    return self.execute_command('GET', name)
  File "/home/airflow/.local/lib/python3.7/site-packages/redis/client.py", line 898, in execute_command
    conn = self.connection or pool.get_connection(command_name, **options)
  File "/home/airflow/.local/lib/python3.7/site-packages/redis/connection.py", line 1192, in get_connection
    connection.connect()
  File "/home/airflow/.local/lib/python3.7/site-packages/redis/connection.py", line 563, in connect
    raise ConnectionError(self._error_message(e))
redis.exceptions.ConnectionError: Error 99 connecting to localhost:6379. Cannot assign requested address.
[2022-11-07T00:31:23.153+0000] {processor.py:768} WARNING - No viable dags retrieved from /opt/airflow/dags/third_dug.py
[2022-11-07T00:31:23.217+0000] {processor.py:176} INFO - Processing /opt/airflow/dags/third_dug.py took 1.848 seconds
[2022-11-07T17:11:01.812+0000] {processor.py:154} INFO - Started process (PID=52210) to work on /opt/airflow/dags/third_dug.py
[2022-11-07T17:11:01.819+0000] {processor.py:756} INFO - Processing file /opt/airflow/dags/third_dug.py for tasks to queue
[2022-11-07T17:11:01.828+0000] {logging_mixin.py:120} INFO - [2022-11-07T17:11:01.828+0000] {dagbag.py:537} INFO - Filling up the DagBag from /opt/airflow/dags/third_dug.py
[2022-11-07T17:11:03.286+0000] {logging_mixin.py:120} INFO - [2022-11-07T17:11:03.266+0000] {dagbag.py:342} ERROR - Failed to import: /opt/airflow/dags/third_dug.py
Traceback (most recent call last):
  File "/home/airflow/.local/lib/python3.7/site-packages/redis/connection.py", line 559, in connect
    sock = self._connect()
  File "/home/airflow/.local/lib/python3.7/site-packages/redis/connection.py", line 615, in _connect
    raise err
  File "/home/airflow/.local/lib/python3.7/site-packages/redis/connection.py", line 603, in _connect
    sock.connect(socket_address)
OSError: [Errno 99] Cannot assign requested address

During handling of the above exception, another exception occurred:

Traceback (most recent call last):
  File "/home/airflow/.local/lib/python3.7/site-packages/airflow/models/dagbag.py", line 338, in parse
    loader.exec_module(new_module)
  File "<frozen importlib._bootstrap_external>", line 728, in exec_module
  File "<frozen importlib._bootstrap>", line 219, in _call_with_frames_removed
  File "/opt/airflow/dags/third_dug.py", line 74, in <module>
    python_callable=table_1_columns()
  File "/opt/airflow/dags/third_dug.py", line 63, in table_1_columns
    blob = r.get('table_1')
  File "/home/airflow/.local/lib/python3.7/site-packages/redis/client.py", line 1606, in get
    return self.execute_command('GET', name)
  File "/home/airflow/.local/lib/python3.7/site-packages/redis/client.py", line 898, in execute_command
    conn = self.connection or pool.get_connection(command_name, **options)
  File "/home/airflow/.local/lib/python3.7/site-packages/redis/connection.py", line 1192, in get_connection
    connection.connect()
  File "/home/airflow/.local/lib/python3.7/site-packages/redis/connection.py", line 563, in connect
    raise ConnectionError(self._error_message(e))
redis.exceptions.ConnectionError: Error 99 connecting to localhost:6379. Cannot assign requested address.
[2022-11-07T17:11:03.296+0000] {processor.py:768} WARNING - No viable dags retrieved from /opt/airflow/dags/third_dug.py
[2022-11-07T17:11:03.354+0000] {processor.py:176} INFO - Processing /opt/airflow/dags/third_dug.py took 1.554 seconds
[2022-11-07T17:11:33.984+0000] {processor.py:154} INFO - Started process (PID=52277) to work on /opt/airflow/dags/third_dug.py
[2022-11-07T17:11:33.986+0000] {processor.py:756} INFO - Processing file /opt/airflow/dags/third_dug.py for tasks to queue
[2022-11-07T17:11:33.987+0000] {logging_mixin.py:120} INFO - [2022-11-07T17:11:33.987+0000] {dagbag.py:537} INFO - Filling up the DagBag from /opt/airflow/dags/third_dug.py
[2022-11-07T17:11:34.296+0000] {logging_mixin.py:120} INFO - [2022-11-07T17:11:34.292+0000] {dagbag.py:342} ERROR - Failed to import: /opt/airflow/dags/third_dug.py
Traceback (most recent call last):
  File "/home/airflow/.local/lib/python3.7/site-packages/redis/connection.py", line 559, in connect
    sock = self._connect()
  File "/home/airflow/.local/lib/python3.7/site-packages/redis/connection.py", line 615, in _connect
    raise err
  File "/home/airflow/.local/lib/python3.7/site-packages/redis/connection.py", line 603, in _connect
    sock.connect(socket_address)
OSError: [Errno 99] Cannot assign requested address

During handling of the above exception, another exception occurred:

Traceback (most recent call last):
  File "/home/airflow/.local/lib/python3.7/site-packages/airflow/models/dagbag.py", line 338, in parse
    loader.exec_module(new_module)
  File "<frozen importlib._bootstrap_external>", line 728, in exec_module
  File "<frozen importlib._bootstrap>", line 219, in _call_with_frames_removed
  File "/opt/airflow/dags/third_dug.py", line 74, in <module>
    python_callable=table_1_columns()
  File "/opt/airflow/dags/third_dug.py", line 63, in table_1_columns
    blob = r.get('table_1')
  File "/home/airflow/.local/lib/python3.7/site-packages/redis/client.py", line 1606, in get
    return self.execute_command('GET', name)
  File "/home/airflow/.local/lib/python3.7/site-packages/redis/client.py", line 898, in execute_command
    conn = self.connection or pool.get_connection(command_name, **options)
  File "/home/airflow/.local/lib/python3.7/site-packages/redis/connection.py", line 1192, in get_connection
    connection.connect()
  File "/home/airflow/.local/lib/python3.7/site-packages/redis/connection.py", line 563, in connect
    raise ConnectionError(self._error_message(e))
redis.exceptions.ConnectionError: Error 99 connecting to localhost:6379. Cannot assign requested address.
[2022-11-07T17:11:34.298+0000] {processor.py:768} WARNING - No viable dags retrieved from /opt/airflow/dags/third_dug.py
[2022-11-07T17:11:34.313+0000] {processor.py:176} INFO - Processing /opt/airflow/dags/third_dug.py took 0.338 seconds
[2022-11-07T17:12:04.719+0000] {processor.py:154} INFO - Started process (PID=52343) to work on /opt/airflow/dags/third_dug.py
[2022-11-07T17:12:04.722+0000] {processor.py:756} INFO - Processing file /opt/airflow/dags/third_dug.py for tasks to queue
[2022-11-07T17:12:04.723+0000] {logging_mixin.py:120} INFO - [2022-11-07T17:12:04.723+0000] {dagbag.py:537} INFO - Filling up the DagBag from /opt/airflow/dags/third_dug.py
[2022-11-07T17:12:05.002+0000] {logging_mixin.py:120} INFO - [2022-11-07T17:12:05.000+0000] {dagbag.py:342} ERROR - Failed to import: /opt/airflow/dags/third_dug.py
Traceback (most recent call last):
  File "/home/airflow/.local/lib/python3.7/site-packages/redis/connection.py", line 559, in connect
    sock = self._connect()
  File "/home/airflow/.local/lib/python3.7/site-packages/redis/connection.py", line 615, in _connect
    raise err
  File "/home/airflow/.local/lib/python3.7/site-packages/redis/connection.py", line 603, in _connect
    sock.connect(socket_address)
OSError: [Errno 99] Cannot assign requested address

During handling of the above exception, another exception occurred:

Traceback (most recent call last):
  File "/home/airflow/.local/lib/python3.7/site-packages/airflow/models/dagbag.py", line 338, in parse
    loader.exec_module(new_module)
  File "<frozen importlib._bootstrap_external>", line 728, in exec_module
  File "<frozen importlib._bootstrap>", line 219, in _call_with_frames_removed
  File "/opt/airflow/dags/third_dug.py", line 74, in <module>
    python_callable=table_1_columns()
  File "/opt/airflow/dags/third_dug.py", line 63, in table_1_columns
    blob = r.get('table_1')
  File "/home/airflow/.local/lib/python3.7/site-packages/redis/client.py", line 1606, in get
    return self.execute_command('GET', name)
  File "/home/airflow/.local/lib/python3.7/site-packages/redis/client.py", line 898, in execute_command
    conn = self.connection or pool.get_connection(command_name, **options)
  File "/home/airflow/.local/lib/python3.7/site-packages/redis/connection.py", line 1192, in get_connection
    connection.connect()
  File "/home/airflow/.local/lib/python3.7/site-packages/redis/connection.py", line 563, in connect
    raise ConnectionError(self._error_message(e))
redis.exceptions.ConnectionError: Error 99 connecting to localhost:6379. Cannot assign requested address.
[2022-11-07T17:12:05.004+0000] {processor.py:768} WARNING - No viable dags retrieved from /opt/airflow/dags/third_dug.py
[2022-11-07T17:12:05.018+0000] {processor.py:176} INFO - Processing /opt/airflow/dags/third_dug.py took 0.306 seconds
[2022-11-07T17:12:35.072+0000] {processor.py:154} INFO - Started process (PID=52411) to work on /opt/airflow/dags/third_dug.py
[2022-11-07T17:12:35.075+0000] {processor.py:756} INFO - Processing file /opt/airflow/dags/third_dug.py for tasks to queue
[2022-11-07T17:12:35.077+0000] {logging_mixin.py:120} INFO - [2022-11-07T17:12:35.076+0000] {dagbag.py:537} INFO - Filling up the DagBag from /opt/airflow/dags/third_dug.py
[2022-11-07T17:12:35.327+0000] {logging_mixin.py:120} INFO - [2022-11-07T17:12:35.325+0000] {dagbag.py:342} ERROR - Failed to import: /opt/airflow/dags/third_dug.py
Traceback (most recent call last):
  File "/home/airflow/.local/lib/python3.7/site-packages/redis/connection.py", line 559, in connect
    sock = self._connect()
  File "/home/airflow/.local/lib/python3.7/site-packages/redis/connection.py", line 615, in _connect
    raise err
  File "/home/airflow/.local/lib/python3.7/site-packages/redis/connection.py", line 603, in _connect
    sock.connect(socket_address)
OSError: [Errno 99] Cannot assign requested address

During handling of the above exception, another exception occurred:

Traceback (most recent call last):
  File "/home/airflow/.local/lib/python3.7/site-packages/airflow/models/dagbag.py", line 338, in parse
    loader.exec_module(new_module)
  File "<frozen importlib._bootstrap_external>", line 728, in exec_module
  File "<frozen importlib._bootstrap>", line 219, in _call_with_frames_removed
  File "/opt/airflow/dags/third_dug.py", line 74, in <module>
    python_callable=table_1_columns()
  File "/opt/airflow/dags/third_dug.py", line 63, in table_1_columns
    blob = r.get('table_1')
  File "/home/airflow/.local/lib/python3.7/site-packages/redis/client.py", line 1606, in get
    return self.execute_command('GET', name)
  File "/home/airflow/.local/lib/python3.7/site-packages/redis/client.py", line 898, in execute_command
    conn = self.connection or pool.get_connection(command_name, **options)
  File "/home/airflow/.local/lib/python3.7/site-packages/redis/connection.py", line 1192, in get_connection
    connection.connect()
  File "/home/airflow/.local/lib/python3.7/site-packages/redis/connection.py", line 563, in connect
    raise ConnectionError(self._error_message(e))
redis.exceptions.ConnectionError: Error 99 connecting to localhost:6379. Cannot assign requested address.
[2022-11-07T17:12:35.336+0000] {processor.py:768} WARNING - No viable dags retrieved from /opt/airflow/dags/third_dug.py
[2022-11-07T17:12:35.351+0000] {processor.py:176} INFO - Processing /opt/airflow/dags/third_dug.py took 0.282 seconds
[2022-11-07T17:13:05.516+0000] {processor.py:154} INFO - Started process (PID=52469) to work on /opt/airflow/dags/third_dug.py
[2022-11-07T17:13:05.520+0000] {processor.py:756} INFO - Processing file /opt/airflow/dags/third_dug.py for tasks to queue
[2022-11-07T17:13:05.522+0000] {logging_mixin.py:120} INFO - [2022-11-07T17:13:05.522+0000] {dagbag.py:537} INFO - Filling up the DagBag from /opt/airflow/dags/third_dug.py
[2022-11-07T17:13:05.801+0000] {logging_mixin.py:120} INFO - [2022-11-07T17:13:05.799+0000] {dagbag.py:342} ERROR - Failed to import: /opt/airflow/dags/third_dug.py
Traceback (most recent call last):
  File "/home/airflow/.local/lib/python3.7/site-packages/redis/connection.py", line 559, in connect
    sock = self._connect()
  File "/home/airflow/.local/lib/python3.7/site-packages/redis/connection.py", line 615, in _connect
    raise err
  File "/home/airflow/.local/lib/python3.7/site-packages/redis/connection.py", line 603, in _connect
    sock.connect(socket_address)
OSError: [Errno 99] Cannot assign requested address

During handling of the above exception, another exception occurred:

Traceback (most recent call last):
  File "/home/airflow/.local/lib/python3.7/site-packages/airflow/models/dagbag.py", line 338, in parse
    loader.exec_module(new_module)
  File "<frozen importlib._bootstrap_external>", line 728, in exec_module
  File "<frozen importlib._bootstrap>", line 219, in _call_with_frames_removed
  File "/opt/airflow/dags/third_dug.py", line 74, in <module>
    python_callable=table_1_columns()
  File "/opt/airflow/dags/third_dug.py", line 63, in table_1_columns
    blob = r.get('table_1')
  File "/home/airflow/.local/lib/python3.7/site-packages/redis/client.py", line 1606, in get
    return self.execute_command('GET', name)
  File "/home/airflow/.local/lib/python3.7/site-packages/redis/client.py", line 898, in execute_command
    conn = self.connection or pool.get_connection(command_name, **options)
  File "/home/airflow/.local/lib/python3.7/site-packages/redis/connection.py", line 1192, in get_connection
    connection.connect()
  File "/home/airflow/.local/lib/python3.7/site-packages/redis/connection.py", line 563, in connect
    raise ConnectionError(self._error_message(e))
redis.exceptions.ConnectionError: Error 99 connecting to localhost:6379. Cannot assign requested address.
[2022-11-07T17:13:05.802+0000] {processor.py:768} WARNING - No viable dags retrieved from /opt/airflow/dags/third_dug.py
[2022-11-07T17:13:05.816+0000] {processor.py:176} INFO - Processing /opt/airflow/dags/third_dug.py took 0.304 seconds
[2022-11-07T17:13:36.673+0000] {processor.py:154} INFO - Started process (PID=52536) to work on /opt/airflow/dags/third_dug.py
[2022-11-07T17:13:36.675+0000] {processor.py:756} INFO - Processing file /opt/airflow/dags/third_dug.py for tasks to queue
[2022-11-07T17:13:36.677+0000] {logging_mixin.py:120} INFO - [2022-11-07T17:13:36.677+0000] {dagbag.py:537} INFO - Filling up the DagBag from /opt/airflow/dags/third_dug.py
[2022-11-07T17:13:36.940+0000] {logging_mixin.py:120} INFO - [2022-11-07T17:13:36.937+0000] {dagbag.py:342} ERROR - Failed to import: /opt/airflow/dags/third_dug.py
Traceback (most recent call last):
  File "/home/airflow/.local/lib/python3.7/site-packages/redis/connection.py", line 559, in connect
    sock = self._connect()
  File "/home/airflow/.local/lib/python3.7/site-packages/redis/connection.py", line 615, in _connect
    raise err
  File "/home/airflow/.local/lib/python3.7/site-packages/redis/connection.py", line 603, in _connect
    sock.connect(socket_address)
OSError: [Errno 99] Cannot assign requested address

During handling of the above exception, another exception occurred:

Traceback (most recent call last):
  File "/home/airflow/.local/lib/python3.7/site-packages/airflow/models/dagbag.py", line 338, in parse
    loader.exec_module(new_module)
  File "<frozen importlib._bootstrap_external>", line 728, in exec_module
  File "<frozen importlib._bootstrap>", line 219, in _call_with_frames_removed
  File "/opt/airflow/dags/third_dug.py", line 74, in <module>
    python_callable=table_1_columns()
  File "/opt/airflow/dags/third_dug.py", line 63, in table_1_columns
    blob = r.get('table_1')
  File "/home/airflow/.local/lib/python3.7/site-packages/redis/client.py", line 1606, in get
    return self.execute_command('GET', name)
  File "/home/airflow/.local/lib/python3.7/site-packages/redis/client.py", line 898, in execute_command
    conn = self.connection or pool.get_connection(command_name, **options)
  File "/home/airflow/.local/lib/python3.7/site-packages/redis/connection.py", line 1192, in get_connection
    connection.connect()
  File "/home/airflow/.local/lib/python3.7/site-packages/redis/connection.py", line 563, in connect
    raise ConnectionError(self._error_message(e))
redis.exceptions.ConnectionError: Error 99 connecting to localhost:6379. Cannot assign requested address.
[2022-11-07T17:13:36.942+0000] {processor.py:768} WARNING - No viable dags retrieved from /opt/airflow/dags/third_dug.py
[2022-11-07T17:13:36.958+0000] {processor.py:176} INFO - Processing /opt/airflow/dags/third_dug.py took 0.289 seconds
[2022-11-07T17:14:07.343+0000] {processor.py:154} INFO - Started process (PID=52603) to work on /opt/airflow/dags/third_dug.py
[2022-11-07T17:14:07.345+0000] {processor.py:756} INFO - Processing file /opt/airflow/dags/third_dug.py for tasks to queue
[2022-11-07T17:14:07.347+0000] {logging_mixin.py:120} INFO - [2022-11-07T17:14:07.347+0000] {dagbag.py:537} INFO - Filling up the DagBag from /opt/airflow/dags/third_dug.py
[2022-11-07T17:14:07.592+0000] {logging_mixin.py:120} INFO - [2022-11-07T17:14:07.590+0000] {dagbag.py:342} ERROR - Failed to import: /opt/airflow/dags/third_dug.py
Traceback (most recent call last):
  File "/home/airflow/.local/lib/python3.7/site-packages/redis/connection.py", line 559, in connect
    sock = self._connect()
  File "/home/airflow/.local/lib/python3.7/site-packages/redis/connection.py", line 615, in _connect
    raise err
  File "/home/airflow/.local/lib/python3.7/site-packages/redis/connection.py", line 603, in _connect
    sock.connect(socket_address)
OSError: [Errno 99] Cannot assign requested address

During handling of the above exception, another exception occurred:

Traceback (most recent call last):
  File "/home/airflow/.local/lib/python3.7/site-packages/airflow/models/dagbag.py", line 338, in parse
    loader.exec_module(new_module)
  File "<frozen importlib._bootstrap_external>", line 728, in exec_module
  File "<frozen importlib._bootstrap>", line 219, in _call_with_frames_removed
  File "/opt/airflow/dags/third_dug.py", line 74, in <module>
    python_callable=table_1_columns()
  File "/opt/airflow/dags/third_dug.py", line 63, in table_1_columns
    blob = r.get('table_1')
  File "/home/airflow/.local/lib/python3.7/site-packages/redis/client.py", line 1606, in get
    return self.execute_command('GET', name)
  File "/home/airflow/.local/lib/python3.7/site-packages/redis/client.py", line 898, in execute_command
    conn = self.connection or pool.get_connection(command_name, **options)
  File "/home/airflow/.local/lib/python3.7/site-packages/redis/connection.py", line 1192, in get_connection
    connection.connect()
  File "/home/airflow/.local/lib/python3.7/site-packages/redis/connection.py", line 563, in connect
    raise ConnectionError(self._error_message(e))
redis.exceptions.ConnectionError: Error 99 connecting to localhost:6379. Cannot assign requested address.
[2022-11-07T17:14:07.594+0000] {processor.py:768} WARNING - No viable dags retrieved from /opt/airflow/dags/third_dug.py
[2022-11-07T17:14:07.609+0000] {processor.py:176} INFO - Processing /opt/airflow/dags/third_dug.py took 0.270 seconds
[2022-11-07T17:14:37.757+0000] {processor.py:154} INFO - Started process (PID=52671) to work on /opt/airflow/dags/third_dug.py
[2022-11-07T17:14:37.760+0000] {processor.py:756} INFO - Processing file /opt/airflow/dags/third_dug.py for tasks to queue
[2022-11-07T17:14:37.761+0000] {logging_mixin.py:120} INFO - [2022-11-07T17:14:37.761+0000] {dagbag.py:537} INFO - Filling up the DagBag from /opt/airflow/dags/third_dug.py
[2022-11-07T17:14:38.031+0000] {logging_mixin.py:120} INFO - [2022-11-07T17:14:38.027+0000] {dagbag.py:342} ERROR - Failed to import: /opt/airflow/dags/third_dug.py
Traceback (most recent call last):
  File "/home/airflow/.local/lib/python3.7/site-packages/redis/connection.py", line 559, in connect
    sock = self._connect()
  File "/home/airflow/.local/lib/python3.7/site-packages/redis/connection.py", line 615, in _connect
    raise err
  File "/home/airflow/.local/lib/python3.7/site-packages/redis/connection.py", line 603, in _connect
    sock.connect(socket_address)
OSError: [Errno 99] Cannot assign requested address

During handling of the above exception, another exception occurred:

Traceback (most recent call last):
  File "/home/airflow/.local/lib/python3.7/site-packages/airflow/models/dagbag.py", line 338, in parse
    loader.exec_module(new_module)
  File "<frozen importlib._bootstrap_external>", line 728, in exec_module
  File "<frozen importlib._bootstrap>", line 219, in _call_with_frames_removed
  File "/opt/airflow/dags/third_dug.py", line 74, in <module>
    python_callable=table_1_columns()
  File "/opt/airflow/dags/third_dug.py", line 63, in table_1_columns
    blob = r.get('table_1')
  File "/home/airflow/.local/lib/python3.7/site-packages/redis/client.py", line 1606, in get
    return self.execute_command('GET', name)
  File "/home/airflow/.local/lib/python3.7/site-packages/redis/client.py", line 898, in execute_command
    conn = self.connection or pool.get_connection(command_name, **options)
  File "/home/airflow/.local/lib/python3.7/site-packages/redis/connection.py", line 1192, in get_connection
    connection.connect()
  File "/home/airflow/.local/lib/python3.7/site-packages/redis/connection.py", line 563, in connect
    raise ConnectionError(self._error_message(e))
redis.exceptions.ConnectionError: Error 99 connecting to localhost:6379. Cannot assign requested address.
[2022-11-07T17:14:38.033+0000] {processor.py:768} WARNING - No viable dags retrieved from /opt/airflow/dags/third_dug.py
[2022-11-07T17:14:38.050+0000] {processor.py:176} INFO - Processing /opt/airflow/dags/third_dug.py took 0.298 seconds
[2022-11-07T17:21:19.123+0000] {processor.py:154} INFO - Started process (PID=52687) to work on /opt/airflow/dags/third_dug.py
[2022-11-07T17:21:19.125+0000] {processor.py:756} INFO - Processing file /opt/airflow/dags/third_dug.py for tasks to queue
[2022-11-07T17:21:19.126+0000] {logging_mixin.py:120} INFO - [2022-11-07T17:21:19.126+0000] {dagbag.py:537} INFO - Filling up the DagBag from /opt/airflow/dags/third_dug.py
[2022-11-07T17:21:19.631+0000] {logging_mixin.py:120} INFO - [2022-11-07T17:21:19.615+0000] {dagbag.py:342} ERROR - Failed to import: /opt/airflow/dags/third_dug.py
Traceback (most recent call last):
  File "/home/airflow/.local/lib/python3.7/site-packages/redis/connection.py", line 559, in connect
    sock = self._connect()
  File "/home/airflow/.local/lib/python3.7/site-packages/redis/connection.py", line 615, in _connect
    raise err
  File "/home/airflow/.local/lib/python3.7/site-packages/redis/connection.py", line 603, in _connect
    sock.connect(socket_address)
OSError: [Errno 99] Cannot assign requested address

During handling of the above exception, another exception occurred:

Traceback (most recent call last):
  File "/home/airflow/.local/lib/python3.7/site-packages/airflow/models/dagbag.py", line 338, in parse
    loader.exec_module(new_module)
  File "<frozen importlib._bootstrap_external>", line 728, in exec_module
  File "<frozen importlib._bootstrap>", line 219, in _call_with_frames_removed
  File "/opt/airflow/dags/third_dug.py", line 74, in <module>
    python_callable=table_1_columns()
  File "/opt/airflow/dags/third_dug.py", line 63, in table_1_columns
    blob = r.get('table_1')
  File "/home/airflow/.local/lib/python3.7/site-packages/redis/client.py", line 1606, in get
    return self.execute_command('GET', name)
  File "/home/airflow/.local/lib/python3.7/site-packages/redis/client.py", line 898, in execute_command
    conn = self.connection or pool.get_connection(command_name, **options)
  File "/home/airflow/.local/lib/python3.7/site-packages/redis/connection.py", line 1192, in get_connection
    connection.connect()
  File "/home/airflow/.local/lib/python3.7/site-packages/redis/connection.py", line 563, in connect
    raise ConnectionError(self._error_message(e))
redis.exceptions.ConnectionError: Error 99 connecting to localhost:6379. Cannot assign requested address.
[2022-11-07T17:21:19.634+0000] {processor.py:768} WARNING - No viable dags retrieved from /opt/airflow/dags/third_dug.py
[2022-11-07T17:21:19.653+0000] {processor.py:176} INFO - Processing /opt/airflow/dags/third_dug.py took 0.532 seconds
[2022-11-07T17:53:14.695+0000] {processor.py:154} INFO - Started process (PID=52756) to work on /opt/airflow/dags/third_dug.py
[2022-11-07T17:53:14.698+0000] {processor.py:756} INFO - Processing file /opt/airflow/dags/third_dug.py for tasks to queue
[2022-11-07T17:53:14.702+0000] {logging_mixin.py:120} INFO - [2022-11-07T17:53:14.701+0000] {dagbag.py:537} INFO - Filling up the DagBag from /opt/airflow/dags/third_dug.py
[2022-11-07T17:53:15.472+0000] {logging_mixin.py:120} INFO - [2022-11-07T17:53:15.465+0000] {dagbag.py:342} ERROR - Failed to import: /opt/airflow/dags/third_dug.py
Traceback (most recent call last):
  File "/home/airflow/.local/lib/python3.7/site-packages/redis/connection.py", line 559, in connect
    sock = self._connect()
  File "/home/airflow/.local/lib/python3.7/site-packages/redis/connection.py", line 615, in _connect
    raise err
  File "/home/airflow/.local/lib/python3.7/site-packages/redis/connection.py", line 603, in _connect
    sock.connect(socket_address)
OSError: [Errno 99] Cannot assign requested address

During handling of the above exception, another exception occurred:

Traceback (most recent call last):
  File "/home/airflow/.local/lib/python3.7/site-packages/airflow/models/dagbag.py", line 338, in parse
    loader.exec_module(new_module)
  File "<frozen importlib._bootstrap_external>", line 728, in exec_module
  File "<frozen importlib._bootstrap>", line 219, in _call_with_frames_removed
  File "/opt/airflow/dags/third_dug.py", line 74, in <module>
    python_callable=table_1_columns()
  File "/opt/airflow/dags/third_dug.py", line 63, in table_1_columns
    blob = r.get('table_1')
  File "/home/airflow/.local/lib/python3.7/site-packages/redis/client.py", line 1606, in get
    return self.execute_command('GET', name)
  File "/home/airflow/.local/lib/python3.7/site-packages/redis/client.py", line 898, in execute_command
    conn = self.connection or pool.get_connection(command_name, **options)
  File "/home/airflow/.local/lib/python3.7/site-packages/redis/connection.py", line 1192, in get_connection
    connection.connect()
  File "/home/airflow/.local/lib/python3.7/site-packages/redis/connection.py", line 563, in connect
    raise ConnectionError(self._error_message(e))
redis.exceptions.ConnectionError: Error 99 connecting to localhost:6379. Cannot assign requested address.
[2022-11-07T17:53:15.474+0000] {processor.py:768} WARNING - No viable dags retrieved from /opt/airflow/dags/third_dug.py
[2022-11-07T17:53:15.504+0000] {processor.py:176} INFO - Processing /opt/airflow/dags/third_dug.py took 0.820 seconds
[2022-11-07T18:20:14.796+0000] {processor.py:154} INFO - Started process (PID=52814) to work on /opt/airflow/dags/third_dug.py
[2022-11-07T18:20:14.800+0000] {processor.py:756} INFO - Processing file /opt/airflow/dags/third_dug.py for tasks to queue
[2022-11-07T18:20:14.801+0000] {logging_mixin.py:120} INFO - [2022-11-07T18:20:14.801+0000] {dagbag.py:537} INFO - Filling up the DagBag from /opt/airflow/dags/third_dug.py
[2022-11-07T18:20:15.048+0000] {logging_mixin.py:120} INFO - [2022-11-07T18:20:15.046+0000] {dagbag.py:342} ERROR - Failed to import: /opt/airflow/dags/third_dug.py
Traceback (most recent call last):
  File "/home/airflow/.local/lib/python3.7/site-packages/redis/connection.py", line 559, in connect
    sock = self._connect()
  File "/home/airflow/.local/lib/python3.7/site-packages/redis/connection.py", line 615, in _connect
    raise err
  File "/home/airflow/.local/lib/python3.7/site-packages/redis/connection.py", line 603, in _connect
    sock.connect(socket_address)
OSError: [Errno 99] Cannot assign requested address

During handling of the above exception, another exception occurred:

Traceback (most recent call last):
  File "/home/airflow/.local/lib/python3.7/site-packages/airflow/models/dagbag.py", line 338, in parse
    loader.exec_module(new_module)
  File "<frozen importlib._bootstrap_external>", line 728, in exec_module
  File "<frozen importlib._bootstrap>", line 219, in _call_with_frames_removed
  File "/opt/airflow/dags/third_dug.py", line 74, in <module>
    python_callable=table_1_columns()
  File "/opt/airflow/dags/third_dug.py", line 63, in table_1_columns
    blob = r.get('table_1')
  File "/home/airflow/.local/lib/python3.7/site-packages/redis/client.py", line 1606, in get
    return self.execute_command('GET', name)
  File "/home/airflow/.local/lib/python3.7/site-packages/redis/client.py", line 898, in execute_command
    conn = self.connection or pool.get_connection(command_name, **options)
  File "/home/airflow/.local/lib/python3.7/site-packages/redis/connection.py", line 1192, in get_connection
    connection.connect()
  File "/home/airflow/.local/lib/python3.7/site-packages/redis/connection.py", line 563, in connect
    raise ConnectionError(self._error_message(e))
redis.exceptions.ConnectionError: Error 99 connecting to localhost:6379. Cannot assign requested address.
[2022-11-07T18:20:15.050+0000] {processor.py:768} WARNING - No viable dags retrieved from /opt/airflow/dags/third_dug.py
[2022-11-07T18:20:15.063+0000] {processor.py:176} INFO - Processing /opt/airflow/dags/third_dug.py took 0.271 seconds
[2022-11-07T19:15:47.663+0000] {processor.py:154} INFO - Started process (PID=52881) to work on /opt/airflow/dags/third_dug.py
[2022-11-07T19:15:47.667+0000] {processor.py:756} INFO - Processing file /opt/airflow/dags/third_dug.py for tasks to queue
[2022-11-07T19:15:47.668+0000] {logging_mixin.py:120} INFO - [2022-11-07T19:15:47.668+0000] {dagbag.py:537} INFO - Filling up the DagBag from /opt/airflow/dags/third_dug.py
[2022-11-07T19:15:48.224+0000] {logging_mixin.py:120} INFO - [2022-11-07T19:15:48.221+0000] {dagbag.py:342} ERROR - Failed to import: /opt/airflow/dags/third_dug.py
Traceback (most recent call last):
  File "/home/airflow/.local/lib/python3.7/site-packages/redis/connection.py", line 559, in connect
    sock = self._connect()
  File "/home/airflow/.local/lib/python3.7/site-packages/redis/connection.py", line 615, in _connect
    raise err
  File "/home/airflow/.local/lib/python3.7/site-packages/redis/connection.py", line 603, in _connect
    sock.connect(socket_address)
OSError: [Errno 99] Cannot assign requested address

During handling of the above exception, another exception occurred:

Traceback (most recent call last):
  File "/home/airflow/.local/lib/python3.7/site-packages/airflow/models/dagbag.py", line 338, in parse
    loader.exec_module(new_module)
  File "<frozen importlib._bootstrap_external>", line 728, in exec_module
  File "<frozen importlib._bootstrap>", line 219, in _call_with_frames_removed
  File "/opt/airflow/dags/third_dug.py", line 74, in <module>
    python_callable=table_1_columns()
  File "/opt/airflow/dags/third_dug.py", line 63, in table_1_columns
    blob = r.get('table_1')
  File "/home/airflow/.local/lib/python3.7/site-packages/redis/client.py", line 1606, in get
    return self.execute_command('GET', name)
  File "/home/airflow/.local/lib/python3.7/site-packages/redis/client.py", line 898, in execute_command
    conn = self.connection or pool.get_connection(command_name, **options)
  File "/home/airflow/.local/lib/python3.7/site-packages/redis/connection.py", line 1192, in get_connection
    connection.connect()
  File "/home/airflow/.local/lib/python3.7/site-packages/redis/connection.py", line 563, in connect
    raise ConnectionError(self._error_message(e))
redis.exceptions.ConnectionError: Error 99 connecting to localhost:6379. Cannot assign requested address.
[2022-11-07T19:15:48.226+0000] {processor.py:768} WARNING - No viable dags retrieved from /opt/airflow/dags/third_dug.py
[2022-11-07T19:15:48.249+0000] {processor.py:176} INFO - Processing /opt/airflow/dags/third_dug.py took 0.593 seconds
[2022-11-07T19:44:39.918+0000] {processor.py:154} INFO - Started process (PID=52938) to work on /opt/airflow/dags/third_dug.py
[2022-11-07T19:44:39.920+0000] {processor.py:756} INFO - Processing file /opt/airflow/dags/third_dug.py for tasks to queue
[2022-11-07T19:44:39.921+0000] {logging_mixin.py:120} INFO - [2022-11-07T19:44:39.921+0000] {dagbag.py:537} INFO - Filling up the DagBag from /opt/airflow/dags/third_dug.py
[2022-11-07T19:44:40.225+0000] {logging_mixin.py:120} INFO - [2022-11-07T19:44:40.222+0000] {dagbag.py:342} ERROR - Failed to import: /opt/airflow/dags/third_dug.py
Traceback (most recent call last):
  File "/home/airflow/.local/lib/python3.7/site-packages/redis/connection.py", line 559, in connect
    sock = self._connect()
  File "/home/airflow/.local/lib/python3.7/site-packages/redis/connection.py", line 615, in _connect
    raise err
  File "/home/airflow/.local/lib/python3.7/site-packages/redis/connection.py", line 603, in _connect
    sock.connect(socket_address)
OSError: [Errno 99] Cannot assign requested address

During handling of the above exception, another exception occurred:

Traceback (most recent call last):
  File "/home/airflow/.local/lib/python3.7/site-packages/airflow/models/dagbag.py", line 338, in parse
    loader.exec_module(new_module)
  File "<frozen importlib._bootstrap_external>", line 728, in exec_module
  File "<frozen importlib._bootstrap>", line 219, in _call_with_frames_removed
  File "/opt/airflow/dags/third_dug.py", line 74, in <module>
    python_callable=table_1_columns()
  File "/opt/airflow/dags/third_dug.py", line 63, in table_1_columns
    blob = r.get('table_1')
  File "/home/airflow/.local/lib/python3.7/site-packages/redis/client.py", line 1606, in get
    return self.execute_command('GET', name)
  File "/home/airflow/.local/lib/python3.7/site-packages/redis/client.py", line 898, in execute_command
    conn = self.connection or pool.get_connection(command_name, **options)
  File "/home/airflow/.local/lib/python3.7/site-packages/redis/connection.py", line 1192, in get_connection
    connection.connect()
  File "/home/airflow/.local/lib/python3.7/site-packages/redis/connection.py", line 563, in connect
    raise ConnectionError(self._error_message(e))
redis.exceptions.ConnectionError: Error 99 connecting to localhost:6379. Cannot assign requested address.
[2022-11-07T19:44:40.226+0000] {processor.py:768} WARNING - No viable dags retrieved from /opt/airflow/dags/third_dug.py
[2022-11-07T19:44:40.244+0000] {processor.py:176} INFO - Processing /opt/airflow/dags/third_dug.py took 0.333 seconds
[2022-11-07T20:51:21.911+0000] {processor.py:154} INFO - Started process (PID=53004) to work on /opt/airflow/dags/third_dug.py
[2022-11-07T20:51:21.912+0000] {processor.py:756} INFO - Processing file /opt/airflow/dags/third_dug.py for tasks to queue
[2022-11-07T20:51:21.914+0000] {logging_mixin.py:120} INFO - [2022-11-07T20:51:21.914+0000] {dagbag.py:537} INFO - Filling up the DagBag from /opt/airflow/dags/third_dug.py
[2022-11-07T20:51:22.191+0000] {logging_mixin.py:120} INFO - [2022-11-07T20:51:22.189+0000] {dagbag.py:342} ERROR - Failed to import: /opt/airflow/dags/third_dug.py
Traceback (most recent call last):
  File "/home/airflow/.local/lib/python3.7/site-packages/redis/connection.py", line 559, in connect
    sock = self._connect()
  File "/home/airflow/.local/lib/python3.7/site-packages/redis/connection.py", line 615, in _connect
    raise err
  File "/home/airflow/.local/lib/python3.7/site-packages/redis/connection.py", line 603, in _connect
    sock.connect(socket_address)
OSError: [Errno 99] Cannot assign requested address

During handling of the above exception, another exception occurred:

Traceback (most recent call last):
  File "/home/airflow/.local/lib/python3.7/site-packages/airflow/models/dagbag.py", line 338, in parse
    loader.exec_module(new_module)
  File "<frozen importlib._bootstrap_external>", line 728, in exec_module
  File "<frozen importlib._bootstrap>", line 219, in _call_with_frames_removed
  File "/opt/airflow/dags/third_dug.py", line 74, in <module>
    python_callable=table_1_columns()
  File "/opt/airflow/dags/third_dug.py", line 63, in table_1_columns
    blob = r.get('table_1')
  File "/home/airflow/.local/lib/python3.7/site-packages/redis/client.py", line 1606, in get
    return self.execute_command('GET', name)
  File "/home/airflow/.local/lib/python3.7/site-packages/redis/client.py", line 898, in execute_command
    conn = self.connection or pool.get_connection(command_name, **options)
  File "/home/airflow/.local/lib/python3.7/site-packages/redis/connection.py", line 1192, in get_connection
    connection.connect()
  File "/home/airflow/.local/lib/python3.7/site-packages/redis/connection.py", line 563, in connect
    raise ConnectionError(self._error_message(e))
redis.exceptions.ConnectionError: Error 99 connecting to localhost:6379. Cannot assign requested address.
[2022-11-07T20:51:22.193+0000] {processor.py:768} WARNING - No viable dags retrieved from /opt/airflow/dags/third_dug.py
[2022-11-07T20:51:22.218+0000] {processor.py:176} INFO - Processing /opt/airflow/dags/third_dug.py took 0.310 seconds
[2022-11-07T21:44:40.040+0000] {processor.py:154} INFO - Started process (PID=53071) to work on /opt/airflow/dags/third_dug.py
[2022-11-07T21:44:40.041+0000] {processor.py:756} INFO - Processing file /opt/airflow/dags/third_dug.py for tasks to queue
[2022-11-07T21:44:40.042+0000] {logging_mixin.py:120} INFO - [2022-11-07T21:44:40.042+0000] {dagbag.py:537} INFO - Filling up the DagBag from /opt/airflow/dags/third_dug.py
[2022-11-07T21:44:40.303+0000] {logging_mixin.py:120} INFO - [2022-11-07T21:44:40.301+0000] {dagbag.py:342} ERROR - Failed to import: /opt/airflow/dags/third_dug.py
Traceback (most recent call last):
  File "/home/airflow/.local/lib/python3.7/site-packages/redis/connection.py", line 559, in connect
    sock = self._connect()
  File "/home/airflow/.local/lib/python3.7/site-packages/redis/connection.py", line 615, in _connect
    raise err
  File "/home/airflow/.local/lib/python3.7/site-packages/redis/connection.py", line 603, in _connect
    sock.connect(socket_address)
OSError: [Errno 99] Cannot assign requested address

During handling of the above exception, another exception occurred:

Traceback (most recent call last):
  File "/home/airflow/.local/lib/python3.7/site-packages/airflow/models/dagbag.py", line 338, in parse
    loader.exec_module(new_module)
  File "<frozen importlib._bootstrap_external>", line 728, in exec_module
  File "<frozen importlib._bootstrap>", line 219, in _call_with_frames_removed
  File "/opt/airflow/dags/third_dug.py", line 74, in <module>
    python_callable=table_1_columns()
  File "/opt/airflow/dags/third_dug.py", line 63, in table_1_columns
    blob = r.get('table_1')
  File "/home/airflow/.local/lib/python3.7/site-packages/redis/client.py", line 1606, in get
    return self.execute_command('GET', name)
  File "/home/airflow/.local/lib/python3.7/site-packages/redis/client.py", line 898, in execute_command
    conn = self.connection or pool.get_connection(command_name, **options)
  File "/home/airflow/.local/lib/python3.7/site-packages/redis/connection.py", line 1192, in get_connection
    connection.connect()
  File "/home/airflow/.local/lib/python3.7/site-packages/redis/connection.py", line 563, in connect
    raise ConnectionError(self._error_message(e))
redis.exceptions.ConnectionError: Error 99 connecting to localhost:6379. Cannot assign requested address.
[2022-11-07T21:44:40.305+0000] {processor.py:768} WARNING - No viable dags retrieved from /opt/airflow/dags/third_dug.py
[2022-11-07T21:44:40.319+0000] {processor.py:176} INFO - Processing /opt/airflow/dags/third_dug.py took 0.283 seconds
[2022-11-07T22:48:44.062+0000] {processor.py:154} INFO - Started process (PID=53137) to work on /opt/airflow/dags/third_dug.py
[2022-11-07T22:48:44.068+0000] {processor.py:756} INFO - Processing file /opt/airflow/dags/third_dug.py for tasks to queue
[2022-11-07T22:48:44.070+0000] {logging_mixin.py:120} INFO - [2022-11-07T22:48:44.069+0000] {dagbag.py:537} INFO - Filling up the DagBag from /opt/airflow/dags/third_dug.py
[2022-11-07T22:48:44.624+0000] {logging_mixin.py:120} INFO - [2022-11-07T22:48:44.619+0000] {dagbag.py:342} ERROR - Failed to import: /opt/airflow/dags/third_dug.py
Traceback (most recent call last):
  File "/home/airflow/.local/lib/python3.7/site-packages/redis/connection.py", line 559, in connect
    sock = self._connect()
  File "/home/airflow/.local/lib/python3.7/site-packages/redis/connection.py", line 615, in _connect
    raise err
  File "/home/airflow/.local/lib/python3.7/site-packages/redis/connection.py", line 603, in _connect
    sock.connect(socket_address)
OSError: [Errno 99] Cannot assign requested address

During handling of the above exception, another exception occurred:

Traceback (most recent call last):
  File "/home/airflow/.local/lib/python3.7/site-packages/airflow/models/dagbag.py", line 338, in parse
    loader.exec_module(new_module)
  File "<frozen importlib._bootstrap_external>", line 728, in exec_module
  File "<frozen importlib._bootstrap>", line 219, in _call_with_frames_removed
  File "/opt/airflow/dags/third_dug.py", line 74, in <module>
    python_callable=table_1_columns()
  File "/opt/airflow/dags/third_dug.py", line 63, in table_1_columns
    blob = r.get('table_1')
  File "/home/airflow/.local/lib/python3.7/site-packages/redis/client.py", line 1606, in get
    return self.execute_command('GET', name)
  File "/home/airflow/.local/lib/python3.7/site-packages/redis/client.py", line 898, in execute_command
    conn = self.connection or pool.get_connection(command_name, **options)
  File "/home/airflow/.local/lib/python3.7/site-packages/redis/connection.py", line 1192, in get_connection
    connection.connect()
  File "/home/airflow/.local/lib/python3.7/site-packages/redis/connection.py", line 563, in connect
    raise ConnectionError(self._error_message(e))
redis.exceptions.ConnectionError: Error 99 connecting to localhost:6379. Cannot assign requested address.
[2022-11-07T22:48:44.625+0000] {processor.py:768} WARNING - No viable dags retrieved from /opt/airflow/dags/third_dug.py
[2022-11-07T22:48:44.643+0000] {processor.py:176} INFO - Processing /opt/airflow/dags/third_dug.py took 0.584 seconds
[2022-11-07T23:21:09.990+0000] {processor.py:154} INFO - Started process (PID=53194) to work on /opt/airflow/dags/third_dug.py
[2022-11-07T23:21:09.993+0000] {processor.py:756} INFO - Processing file /opt/airflow/dags/third_dug.py for tasks to queue
[2022-11-07T23:21:09.995+0000] {logging_mixin.py:120} INFO - [2022-11-07T23:21:09.995+0000] {dagbag.py:537} INFO - Filling up the DagBag from /opt/airflow/dags/third_dug.py
[2022-11-07T23:21:11.178+0000] {logging_mixin.py:120} INFO - [2022-11-07T23:21:11.171+0000] {dagbag.py:342} ERROR - Failed to import: /opt/airflow/dags/third_dug.py
Traceback (most recent call last):
  File "/home/airflow/.local/lib/python3.7/site-packages/redis/connection.py", line 559, in connect
    sock = self._connect()
  File "/home/airflow/.local/lib/python3.7/site-packages/redis/connection.py", line 615, in _connect
    raise err
  File "/home/airflow/.local/lib/python3.7/site-packages/redis/connection.py", line 603, in _connect
    sock.connect(socket_address)
OSError: [Errno 99] Cannot assign requested address

During handling of the above exception, another exception occurred:

Traceback (most recent call last):
  File "/home/airflow/.local/lib/python3.7/site-packages/airflow/models/dagbag.py", line 338, in parse
    loader.exec_module(new_module)
  File "<frozen importlib._bootstrap_external>", line 728, in exec_module
  File "<frozen importlib._bootstrap>", line 219, in _call_with_frames_removed
  File "/opt/airflow/dags/third_dug.py", line 74, in <module>
    python_callable=table_1_columns()
  File "/opt/airflow/dags/third_dug.py", line 63, in table_1_columns
    blob = r.get('table_1')
  File "/home/airflow/.local/lib/python3.7/site-packages/redis/client.py", line 1606, in get
    return self.execute_command('GET', name)
  File "/home/airflow/.local/lib/python3.7/site-packages/redis/client.py", line 898, in execute_command
    conn = self.connection or pool.get_connection(command_name, **options)
  File "/home/airflow/.local/lib/python3.7/site-packages/redis/connection.py", line 1192, in get_connection
    connection.connect()
  File "/home/airflow/.local/lib/python3.7/site-packages/redis/connection.py", line 563, in connect
    raise ConnectionError(self._error_message(e))
redis.exceptions.ConnectionError: Error 99 connecting to localhost:6379. Cannot assign requested address.
[2022-11-07T23:21:11.182+0000] {processor.py:768} WARNING - No viable dags retrieved from /opt/airflow/dags/third_dug.py
[2022-11-07T23:21:11.221+0000] {processor.py:176} INFO - Processing /opt/airflow/dags/third_dug.py took 1.239 seconds
[2022-11-07T23:58:52.624+0000] {processor.py:154} INFO - Started process (PID=53261) to work on /opt/airflow/dags/third_dug.py
[2022-11-07T23:58:52.626+0000] {processor.py:756} INFO - Processing file /opt/airflow/dags/third_dug.py for tasks to queue
[2022-11-07T23:58:52.628+0000] {logging_mixin.py:120} INFO - [2022-11-07T23:58:52.628+0000] {dagbag.py:537} INFO - Filling up the DagBag from /opt/airflow/dags/third_dug.py
[2022-11-07T23:58:53.128+0000] {logging_mixin.py:120} INFO - [2022-11-07T23:58:53.123+0000] {dagbag.py:342} ERROR - Failed to import: /opt/airflow/dags/third_dug.py
Traceback (most recent call last):
  File "/home/airflow/.local/lib/python3.7/site-packages/redis/connection.py", line 559, in connect
    sock = self._connect()
  File "/home/airflow/.local/lib/python3.7/site-packages/redis/connection.py", line 615, in _connect
    raise err
  File "/home/airflow/.local/lib/python3.7/site-packages/redis/connection.py", line 603, in _connect
    sock.connect(socket_address)
OSError: [Errno 99] Cannot assign requested address

During handling of the above exception, another exception occurred:

Traceback (most recent call last):
  File "/home/airflow/.local/lib/python3.7/site-packages/airflow/models/dagbag.py", line 338, in parse
    loader.exec_module(new_module)
  File "<frozen importlib._bootstrap_external>", line 728, in exec_module
  File "<frozen importlib._bootstrap>", line 219, in _call_with_frames_removed
  File "/opt/airflow/dags/third_dug.py", line 74, in <module>
    python_callable=table_1_columns()
  File "/opt/airflow/dags/third_dug.py", line 63, in table_1_columns
    blob = r.get('table_1')
  File "/home/airflow/.local/lib/python3.7/site-packages/redis/client.py", line 1606, in get
    return self.execute_command('GET', name)
  File "/home/airflow/.local/lib/python3.7/site-packages/redis/client.py", line 898, in execute_command
    conn = self.connection or pool.get_connection(command_name, **options)
  File "/home/airflow/.local/lib/python3.7/site-packages/redis/connection.py", line 1192, in get_connection
    connection.connect()
  File "/home/airflow/.local/lib/python3.7/site-packages/redis/connection.py", line 563, in connect
    raise ConnectionError(self._error_message(e))
redis.exceptions.ConnectionError: Error 99 connecting to localhost:6379. Cannot assign requested address.
[2022-11-07T23:58:53.130+0000] {processor.py:768} WARNING - No viable dags retrieved from /opt/airflow/dags/third_dug.py
[2022-11-07T23:58:53.152+0000] {processor.py:176} INFO - Processing /opt/airflow/dags/third_dug.py took 0.531 seconds
