[2022-11-10T16:38:03.310+0000] {taskinstance.py:1165} INFO - Dependencies all met for <TaskInstance: a_fourth_dug.cat_dir manual__2022-11-10T16:37:57.486937+00:00 [queued]>
[2022-11-10T16:38:03.318+0000] {taskinstance.py:1165} INFO - Dependencies all met for <TaskInstance: a_fourth_dug.cat_dir manual__2022-11-10T16:37:57.486937+00:00 [queued]>
[2022-11-10T16:38:03.319+0000] {taskinstance.py:1362} INFO - 
--------------------------------------------------------------------------------
[2022-11-10T16:38:03.320+0000] {taskinstance.py:1363} INFO - Starting attempt 1 of 1
[2022-11-10T16:38:03.341+0000] {taskinstance.py:1364} INFO - 
--------------------------------------------------------------------------------
[2022-11-10T16:38:03.350+0000] {taskinstance.py:1383} INFO - Executing <Task(BashOperator): cat_dir> on 2022-11-10 16:37:57.486937+00:00
[2022-11-10T16:38:03.356+0000] {standard_task_runner.py:55} INFO - Started process 6123 to run task
[2022-11-10T16:38:03.361+0000] {standard_task_runner.py:82} INFO - Running: ['***', 'tasks', 'run', 'a_fourth_dug', 'cat_dir', 'manual__2022-11-10T16:37:57.486937+00:00', '--job-id', '31', '--raw', '--subdir', 'DAGS_FOLDER/fourth_dug.py', '--cfg-path', '/tmp/tmpdmyrll9k']
[2022-11-10T16:38:03.362+0000] {standard_task_runner.py:83} INFO - Job 31: Subtask cat_dir
[2022-11-10T16:38:03.418+0000] {task_command.py:376} INFO - Running <TaskInstance: a_fourth_dug.cat_dir manual__2022-11-10T16:37:57.486937+00:00 [running]> on host 0b03955da713
[2022-11-10T16:38:03.467+0000] {taskinstance.py:1592} INFO - Exporting the following env vars:
AIRFLOW_CTX_DAG_OWNER=eugeny
AIRFLOW_CTX_DAG_ID=a_fourth_dug
AIRFLOW_CTX_TASK_ID=cat_dir
AIRFLOW_CTX_EXECUTION_DATE=2022-11-10T16:37:57.486937+00:00
AIRFLOW_CTX_TRY_NUMBER=1
AIRFLOW_CTX_DAG_RUN_ID=manual__2022-11-10T16:37:57.486937+00:00
[2022-11-10T16:38:03.469+0000] {subprocess.py:63} INFO - Tmp dir root location: 
 /tmp
[2022-11-10T16:38:03.474+0000] {subprocess.py:75} INFO - Running command: ['/bin/bash', '-c', 'cat test_directory']
[2022-11-10T16:38:03.489+0000] {subprocess.py:86} INFO - Output:
[2022-11-10T16:38:03.498+0000] {subprocess.py:93} INFO - cat: test_directory: No such file or directory
[2022-11-10T16:38:03.499+0000] {subprocess.py:97} INFO - Command exited with return code 1
[2022-11-10T16:38:03.510+0000] {taskinstance.py:1851} ERROR - Task failed with exception
Traceback (most recent call last):
  File "/home/airflow/.local/lib/python3.7/site-packages/airflow/operators/bash.py", line 197, in execute
    f'Bash command failed. The command returned a non-zero exit code {result.exit_code}.'
airflow.exceptions.AirflowException: Bash command failed. The command returned a non-zero exit code 1.
[2022-11-10T16:38:03.514+0000] {taskinstance.py:1406} INFO - Marking task as FAILED. dag_id=a_fourth_dug, task_id=cat_dir, execution_date=20221110T163757, start_date=20221110T163803, end_date=20221110T163803
[2022-11-10T16:38:03.522+0000] {standard_task_runner.py:105} ERROR - Failed to execute job 31 for task cat_dir (Bash command failed. The command returned a non-zero exit code 1.; 6123)
[2022-11-10T16:38:03.533+0000] {local_task_job.py:164} INFO - Task exited with return code 1
[2022-11-10T16:38:03.557+0000] {local_task_job.py:273} INFO - 0 downstream tasks scheduled from follow-on schedule check
