[2022-11-22T01:11:29.893+0000] {taskinstance.py:1165} INFO - Dependencies all met for <TaskInstance: PG_to_S3.PG_to_S3 manual__2022-11-21T21:26:12.692587+00:00 [queued]>
[2022-11-22T01:11:29.903+0000] {taskinstance.py:1165} INFO - Dependencies all met for <TaskInstance: PG_to_S3.PG_to_S3 manual__2022-11-21T21:26:12.692587+00:00 [queued]>
[2022-11-22T01:11:29.905+0000] {taskinstance.py:1362} INFO - 
--------------------------------------------------------------------------------
[2022-11-22T01:11:29.907+0000] {taskinstance.py:1363} INFO - Starting attempt 66 of 66
[2022-11-22T01:11:29.909+0000] {taskinstance.py:1364} INFO - 
--------------------------------------------------------------------------------
[2022-11-22T01:11:29.923+0000] {taskinstance.py:1383} INFO - Executing <Task(PostgresToS3Operator): PG_to_S3> on 2022-11-21 21:26:12.692587+00:00
[2022-11-22T01:11:29.930+0000] {standard_task_runner.py:55} INFO - Started process 28414 to run task
[2022-11-22T01:11:29.935+0000] {standard_task_runner.py:82} INFO - Running: ['***', 'tasks', 'run', 'PG_to_S3', 'PG_to_S3', 'manual__2022-11-21T21:26:12.692587+00:00', '--job-id', '180', '--raw', '--subdir', 'DAGS_FOLDER/PGtoS3.py', '--cfg-path', '/tmp/tmpk0aajln7']
[2022-11-22T01:11:29.938+0000] {standard_task_runner.py:83} INFO - Job 180: Subtask PG_to_S3
[2022-11-22T01:11:30.017+0000] {task_command.py:376} INFO - Running <TaskInstance: PG_to_S3.PG_to_S3 manual__2022-11-21T21:26:12.692587+00:00 [running]> on host b785e9657fa7
[2022-11-22T01:11:30.078+0000] {taskinstance.py:1592} INFO - Exporting the following env vars:
AIRFLOW_CTX_DAG_OWNER=eugeny
AIRFLOW_CTX_DAG_ID=PG_to_S3
AIRFLOW_CTX_TASK_ID=PG_to_S3
AIRFLOW_CTX_EXECUTION_DATE=2022-11-21T21:26:12.692587+00:00
AIRFLOW_CTX_TRY_NUMBER=66
AIRFLOW_CTX_DAG_RUN_ID=manual__2022-11-21T21:26:12.692587+00:00
[2022-11-22T01:11:30.376+0000] {taskinstance.py:1851} ERROR - Task failed with exception
Traceback (most recent call last):
  File "/opt/airflow/plugins/operators/pgtos3.py", line 30, in execute
    self.s3().Bucket(self.bucket).load_file(self.filename, self.postgres())
AttributeError: 's3.Bucket' object has no attribute 'load_file'
[2022-11-22T01:11:30.398+0000] {taskinstance.py:1406} INFO - Marking task as FAILED. dag_id=PG_to_S3, task_id=PG_to_S3, execution_date=20221121T212612, start_date=20221122T011129, end_date=20221122T011130
[2022-11-22T01:11:30.417+0000] {standard_task_runner.py:105} ERROR - Failed to execute job 180 for task PG_to_S3 ('s3.Bucket' object has no attribute 'load_file'; 28414)
[2022-11-22T01:11:30.479+0000] {local_task_job.py:164} INFO - Task exited with return code 1
[2022-11-22T01:11:30.503+0000] {local_task_job.py:273} INFO - 0 downstream tasks scheduled from follow-on schedule check
