[2022-11-21T23:18:31.829+0000] {taskinstance.py:1165} INFO - Dependencies all met for <TaskInstance: PG_to_S3.PG_to_S3 manual__2022-11-21T21:26:12.692587+00:00 [queued]>
[2022-11-21T23:18:31.839+0000] {taskinstance.py:1165} INFO - Dependencies all met for <TaskInstance: PG_to_S3.PG_to_S3 manual__2022-11-21T21:26:12.692587+00:00 [queued]>
[2022-11-21T23:18:31.841+0000] {taskinstance.py:1362} INFO - 
--------------------------------------------------------------------------------
[2022-11-21T23:18:31.842+0000] {taskinstance.py:1363} INFO - Starting attempt 42 of 42
[2022-11-21T23:18:31.843+0000] {taskinstance.py:1364} INFO - 
--------------------------------------------------------------------------------
[2022-11-21T23:18:31.856+0000] {taskinstance.py:1383} INFO - Executing <Task(PostgresToS3Operator): PG_to_S3> on 2022-11-21 21:26:12.692587+00:00
[2022-11-21T23:18:31.865+0000] {standard_task_runner.py:55} INFO - Started process 22942 to run task
[2022-11-21T23:18:31.871+0000] {standard_task_runner.py:82} INFO - Running: ['***', 'tasks', 'run', 'PG_to_S3', 'PG_to_S3', 'manual__2022-11-21T21:26:12.692587+00:00', '--job-id', '151', '--raw', '--subdir', 'DAGS_FOLDER/PGtoS3.py', '--cfg-path', '/tmp/tmp0lsxcbfn']
[2022-11-21T23:18:31.877+0000] {standard_task_runner.py:83} INFO - Job 151: Subtask PG_to_S3
[2022-11-21T23:18:31.960+0000] {task_command.py:376} INFO - Running <TaskInstance: PG_to_S3.PG_to_S3 manual__2022-11-21T21:26:12.692587+00:00 [running]> on host b785e9657fa7
[2022-11-21T23:18:32.029+0000] {taskinstance.py:1592} INFO - Exporting the following env vars:
AIRFLOW_CTX_DAG_OWNER=eugeny
AIRFLOW_CTX_DAG_ID=PG_to_S3
AIRFLOW_CTX_TASK_ID=PG_to_S3
AIRFLOW_CTX_EXECUTION_DATE=2022-11-21T21:26:12.692587+00:00
AIRFLOW_CTX_TRY_NUMBER=42
AIRFLOW_CTX_DAG_RUN_ID=manual__2022-11-21T21:26:12.692587+00:00
[2022-11-21T23:18:32.340+0000] {taskinstance.py:1851} ERROR - Task failed with exception
Traceback (most recent call last):
  File "/opt/airflow/plugins/operators/pgtos3.py", line 27, in execute
    self.s3().upload_file(self.postgres(),self.bucket, self.filename)
AttributeError: 's3.ServiceResource' object has no attribute 'upload_file'
[2022-11-21T23:18:32.356+0000] {taskinstance.py:1406} INFO - Marking task as FAILED. dag_id=PG_to_S3, task_id=PG_to_S3, execution_date=20221121T212612, start_date=20221121T231831, end_date=20221121T231832
[2022-11-21T23:18:32.370+0000] {standard_task_runner.py:105} ERROR - Failed to execute job 151 for task PG_to_S3 ('s3.ServiceResource' object has no attribute 'upload_file'; 22942)
[2022-11-21T23:18:32.441+0000] {local_task_job.py:164} INFO - Task exited with return code 1
[2022-11-21T23:18:32.469+0000] {local_task_job.py:273} INFO - 0 downstream tasks scheduled from follow-on schedule check
