[2022-11-22T02:29:58.972+0000] {taskinstance.py:1165} INFO - Dependencies all met for <TaskInstance: PG_to_S3.PG_to_S3 manual__2022-11-21T21:26:12.692587+00:00 [queued]>
[2022-11-22T02:29:58.986+0000] {taskinstance.py:1165} INFO - Dependencies all met for <TaskInstance: PG_to_S3.PG_to_S3 manual__2022-11-21T21:26:12.692587+00:00 [queued]>
[2022-11-22T02:29:58.987+0000] {taskinstance.py:1362} INFO - 
--------------------------------------------------------------------------------
[2022-11-22T02:29:58.988+0000] {taskinstance.py:1363} INFO - Starting attempt 97 of 97
[2022-11-22T02:29:58.990+0000] {taskinstance.py:1364} INFO - 
--------------------------------------------------------------------------------
[2022-11-22T02:29:59.000+0000] {taskinstance.py:1383} INFO - Executing <Task(PostgresToS3Operator): PG_to_S3> on 2022-11-21 21:26:12.692587+00:00
[2022-11-22T02:29:59.007+0000] {standard_task_runner.py:55} INFO - Started process 32326 to run task
[2022-11-22T02:29:59.012+0000] {standard_task_runner.py:82} INFO - Running: ['***', 'tasks', 'run', 'PG_to_S3', 'PG_to_S3', 'manual__2022-11-21T21:26:12.692587+00:00', '--job-id', '211', '--raw', '--subdir', 'DAGS_FOLDER/PGtoS3.py', '--cfg-path', '/tmp/tmpw91c95qe']
[2022-11-22T02:29:59.015+0000] {standard_task_runner.py:83} INFO - Job 211: Subtask PG_to_S3
[2022-11-22T02:29:59.121+0000] {task_command.py:376} INFO - Running <TaskInstance: PG_to_S3.PG_to_S3 manual__2022-11-21T21:26:12.692587+00:00 [running]> on host b785e9657fa7
[2022-11-22T02:29:59.183+0000] {taskinstance.py:1592} INFO - Exporting the following env vars:
AIRFLOW_CTX_DAG_OWNER=eugeny
AIRFLOW_CTX_DAG_ID=PG_to_S3
AIRFLOW_CTX_TASK_ID=PG_to_S3
AIRFLOW_CTX_EXECUTION_DATE=2022-11-21T21:26:12.692587+00:00
AIRFLOW_CTX_TRY_NUMBER=97
AIRFLOW_CTX_DAG_RUN_ID=manual__2022-11-21T21:26:12.692587+00:00
[2022-11-22T02:30:00.888+0000] {taskinstance.py:1851} ERROR - Task failed with exception
Traceback (most recent call last):
  File "/opt/airflow/plugins/operators/pgtos3.py", line 30, in execute
    self.s3()
  File "/opt/airflow/plugins/operators/pgtos3.py", line 63, in s3
    return object.put(Body=data)
  File "/home/airflow/.local/lib/python3.7/site-packages/boto3/resources/factory.py", line 580, in do_action
    response = action(self, *args, **kwargs)
  File "/home/airflow/.local/lib/python3.7/site-packages/boto3/resources/action.py", line 88, in __call__
    response = getattr(parent.meta.client, operation_name)(*args, **params)
  File "/home/airflow/.local/lib/python3.7/site-packages/botocore/client.py", line 514, in _api_call
    return self._make_api_call(operation_name, kwargs)
  File "/home/airflow/.local/lib/python3.7/site-packages/botocore/client.py", line 902, in _make_api_call
    api_params, operation_model, context=request_context
  File "/home/airflow/.local/lib/python3.7/site-packages/botocore/client.py", line 963, in _convert_to_request_dict
    api_params, operation_model
  File "/home/airflow/.local/lib/python3.7/site-packages/botocore/validate.py", line 381, in serialize_to_request
    raise ParamValidationError(report=report.generate_report())
botocore.exceptions.ParamValidationError: Parameter validation failed:
Invalid type for parameter Body, value: None, type: <class 'NoneType'>, valid types: <class 'bytes'>, <class 'bytearray'>, file-like object
[2022-11-22T02:30:00.930+0000] {taskinstance.py:1406} INFO - Marking task as FAILED. dag_id=PG_to_S3, task_id=PG_to_S3, execution_date=20221121T212612, start_date=20221122T022958, end_date=20221122T023000
[2022-11-22T02:30:00.954+0000] {standard_task_runner.py:105} ERROR - Failed to execute job 211 for task PG_to_S3 (Parameter validation failed:
Invalid type for parameter Body, value: None, type: <class 'NoneType'>, valid types: <class 'bytes'>, <class 'bytearray'>, file-like object; 32326)
[2022-11-22T02:30:01.030+0000] {local_task_job.py:164} INFO - Task exited with return code 1
[2022-11-22T02:30:01.052+0000] {local_task_job.py:273} INFO - 0 downstream tasks scheduled from follow-on schedule check
