[2022-11-22T01:27:49.377+0000] {taskinstance.py:1165} INFO - Dependencies all met for <TaskInstance: PG_to_S3.PG_to_S3 manual__2022-11-21T21:26:12.692587+00:00 [queued]>
[2022-11-22T01:27:49.390+0000] {taskinstance.py:1165} INFO - Dependencies all met for <TaskInstance: PG_to_S3.PG_to_S3 manual__2022-11-21T21:26:12.692587+00:00 [queued]>
[2022-11-22T01:27:49.393+0000] {taskinstance.py:1362} INFO - 
--------------------------------------------------------------------------------
[2022-11-22T01:27:49.397+0000] {taskinstance.py:1363} INFO - Starting attempt 77 of 77
[2022-11-22T01:27:49.401+0000] {taskinstance.py:1364} INFO - 
--------------------------------------------------------------------------------
[2022-11-22T01:27:49.420+0000] {taskinstance.py:1383} INFO - Executing <Task(PostgresToS3Operator): PG_to_S3> on 2022-11-21 21:26:12.692587+00:00
[2022-11-22T01:27:49.431+0000] {standard_task_runner.py:55} INFO - Started process 29252 to run task
[2022-11-22T01:27:49.439+0000] {standard_task_runner.py:82} INFO - Running: ['***', 'tasks', 'run', 'PG_to_S3', 'PG_to_S3', 'manual__2022-11-21T21:26:12.692587+00:00', '--job-id', '191', '--raw', '--subdir', 'DAGS_FOLDER/PGtoS3.py', '--cfg-path', '/tmp/tmp8v1qxupw']
[2022-11-22T01:27:49.444+0000] {standard_task_runner.py:83} INFO - Job 191: Subtask PG_to_S3
[2022-11-22T01:27:49.604+0000] {task_command.py:376} INFO - Running <TaskInstance: PG_to_S3.PG_to_S3 manual__2022-11-21T21:26:12.692587+00:00 [running]> on host b785e9657fa7
[2022-11-22T01:27:49.703+0000] {taskinstance.py:1592} INFO - Exporting the following env vars:
AIRFLOW_CTX_DAG_OWNER=eugeny
AIRFLOW_CTX_DAG_ID=PG_to_S3
AIRFLOW_CTX_TASK_ID=PG_to_S3
AIRFLOW_CTX_EXECUTION_DATE=2022-11-21T21:26:12.692587+00:00
AIRFLOW_CTX_TRY_NUMBER=77
AIRFLOW_CTX_DAG_RUN_ID=manual__2022-11-21T21:26:12.692587+00:00
[2022-11-22T01:27:51.459+0000] {taskinstance.py:1851} ERROR - Task failed with exception
Traceback (most recent call last):
  File "/opt/airflow/plugins/operators/pgtos3.py", line 30, in execute
    self.s3().Bucket(self.bucket).upload_file(self.filename, self.postgres())
  File "/opt/airflow/plugins/operators/pgtos3.py", line 42, in postgres
    with open ('~')as f:
FileNotFoundError: [Errno 2] No such file or directory: '~'
[2022-11-22T01:27:51.472+0000] {taskinstance.py:1406} INFO - Marking task as FAILED. dag_id=PG_to_S3, task_id=PG_to_S3, execution_date=20221121T212612, start_date=20221122T012749, end_date=20221122T012751
[2022-11-22T01:27:51.482+0000] {standard_task_runner.py:105} ERROR - Failed to execute job 191 for task PG_to_S3 ([Errno 2] No such file or directory: '~'; 29252)
[2022-11-22T01:27:51.525+0000] {local_task_job.py:164} INFO - Task exited with return code 1
[2022-11-22T01:27:51.544+0000] {local_task_job.py:273} INFO - 0 downstream tasks scheduled from follow-on schedule check
