[2022-11-21T21:45:50.063+0000] {taskinstance.py:1165} INFO - Dependencies all met for <TaskInstance: PG_to_S3.PG_to_S3 manual__2022-11-21T21:26:12.692587+00:00 [queued]>
[2022-11-21T21:45:50.073+0000] {taskinstance.py:1165} INFO - Dependencies all met for <TaskInstance: PG_to_S3.PG_to_S3 manual__2022-11-21T21:26:12.692587+00:00 [queued]>
[2022-11-21T21:45:50.076+0000] {taskinstance.py:1362} INFO - 
--------------------------------------------------------------------------------
[2022-11-21T21:45:50.077+0000] {taskinstance.py:1363} INFO - Starting attempt 4 of 4
[2022-11-21T21:45:50.078+0000] {taskinstance.py:1364} INFO - 
--------------------------------------------------------------------------------
[2022-11-21T21:45:50.092+0000] {taskinstance.py:1383} INFO - Executing <Task(PostgresToS3Operator): PG_to_S3> on 2022-11-21 21:26:12.692587+00:00
[2022-11-21T21:45:50.101+0000] {standard_task_runner.py:55} INFO - Started process 18391 to run task
[2022-11-21T21:45:50.106+0000] {standard_task_runner.py:82} INFO - Running: ['***', 'tasks', 'run', 'PG_to_S3', 'PG_to_S3', 'manual__2022-11-21T21:26:12.692587+00:00', '--job-id', '113', '--raw', '--subdir', 'DAGS_FOLDER/PGtoS3.py', '--cfg-path', '/tmp/tmpwr9jksmk']
[2022-11-21T21:45:50.108+0000] {standard_task_runner.py:83} INFO - Job 113: Subtask PG_to_S3
[2022-11-21T21:45:50.188+0000] {task_command.py:376} INFO - Running <TaskInstance: PG_to_S3.PG_to_S3 manual__2022-11-21T21:26:12.692587+00:00 [running]> on host b785e9657fa7
[2022-11-21T21:45:50.255+0000] {taskinstance.py:1592} INFO - Exporting the following env vars:
AIRFLOW_CTX_DAG_OWNER=eugeny
AIRFLOW_CTX_DAG_ID=PG_to_S3
AIRFLOW_CTX_TASK_ID=PG_to_S3
AIRFLOW_CTX_EXECUTION_DATE=2022-11-21T21:26:12.692587+00:00
AIRFLOW_CTX_TRY_NUMBER=4
AIRFLOW_CTX_DAG_RUN_ID=manual__2022-11-21T21:26:12.692587+00:00
[2022-11-21T21:45:50.259+0000] {taskinstance.py:1851} ERROR - Task failed with exception
Traceback (most recent call last):
  File "/opt/airflow/plugins/operators/pgtos3.py", line 50, in execute
    s3 = s3()
UnboundLocalError: local variable 's3' referenced before assignment
[2022-11-21T21:45:50.276+0000] {taskinstance.py:1406} INFO - Marking task as FAILED. dag_id=PG_to_S3, task_id=PG_to_S3, execution_date=20221121T212612, start_date=20221121T214550, end_date=20221121T214550
[2022-11-21T21:45:50.288+0000] {standard_task_runner.py:105} ERROR - Failed to execute job 113 for task PG_to_S3 (local variable 's3' referenced before assignment; 18391)
[2022-11-21T21:45:50.322+0000] {local_task_job.py:164} INFO - Task exited with return code 1
[2022-11-21T21:45:50.344+0000] {local_task_job.py:273} INFO - 0 downstream tasks scheduled from follow-on schedule check
