[2022-11-21T22:56:30.894+0000] {taskinstance.py:1165} INFO - Dependencies all met for <TaskInstance: PG_to_S3.PG_to_S3 manual__2022-11-21T21:26:12.692587+00:00 [queued]>
[2022-11-21T22:56:30.909+0000] {taskinstance.py:1165} INFO - Dependencies all met for <TaskInstance: PG_to_S3.PG_to_S3 manual__2022-11-21T21:26:12.692587+00:00 [queued]>
[2022-11-21T22:56:30.912+0000] {taskinstance.py:1362} INFO - 
--------------------------------------------------------------------------------
[2022-11-21T22:56:30.914+0000] {taskinstance.py:1363} INFO - Starting attempt 29 of 29
[2022-11-21T22:56:30.917+0000] {taskinstance.py:1364} INFO - 
--------------------------------------------------------------------------------
[2022-11-21T22:56:30.933+0000] {taskinstance.py:1383} INFO - Executing <Task(PostgresToS3Operator): PG_to_S3> on 2022-11-21 21:26:12.692587+00:00
[2022-11-21T22:56:30.946+0000] {standard_task_runner.py:55} INFO - Started process 21838 to run task
[2022-11-21T22:56:30.954+0000] {standard_task_runner.py:82} INFO - Running: ['***', 'tasks', 'run', 'PG_to_S3', 'PG_to_S3', 'manual__2022-11-21T21:26:12.692587+00:00', '--job-id', '138', '--raw', '--subdir', 'DAGS_FOLDER/PGtoS3.py', '--cfg-path', '/tmp/tmp5ms2lsuj']
[2022-11-21T22:56:30.959+0000] {standard_task_runner.py:83} INFO - Job 138: Subtask PG_to_S3
[2022-11-21T22:56:31.075+0000] {task_command.py:376} INFO - Running <TaskInstance: PG_to_S3.PG_to_S3 manual__2022-11-21T21:26:12.692587+00:00 [running]> on host b785e9657fa7
[2022-11-21T22:56:31.151+0000] {taskinstance.py:1592} INFO - Exporting the following env vars:
AIRFLOW_CTX_DAG_OWNER=eugeny
AIRFLOW_CTX_DAG_ID=PG_to_S3
AIRFLOW_CTX_TASK_ID=PG_to_S3
AIRFLOW_CTX_EXECUTION_DATE=2022-11-21T21:26:12.692587+00:00
AIRFLOW_CTX_TRY_NUMBER=29
AIRFLOW_CTX_DAG_RUN_ID=manual__2022-11-21T21:26:12.692587+00:00
[2022-11-21T22:56:32.839+0000] {taskinstance.py:1851} ERROR - Task failed with exception
Traceback (most recent call last):
  File "/opt/airflow/plugins/operators/pgtos3.py", line 27, in execute
    self.s3().Bucket(self.bucket).upload_file(self.postgres())
TypeError: bucket_upload_file() missing 1 required positional argument: 'Key'
[2022-11-21T22:56:32.871+0000] {taskinstance.py:1406} INFO - Marking task as FAILED. dag_id=PG_to_S3, task_id=PG_to_S3, execution_date=20221121T212612, start_date=20221121T225630, end_date=20221121T225632
[2022-11-21T22:56:32.889+0000] {standard_task_runner.py:105} ERROR - Failed to execute job 138 for task PG_to_S3 (bucket_upload_file() missing 1 required positional argument: 'Key'; 21838)
[2022-11-21T22:56:32.956+0000] {local_task_job.py:164} INFO - Task exited with return code 1
[2022-11-21T22:56:32.977+0000] {local_task_job.py:273} INFO - 0 downstream tasks scheduled from follow-on schedule check
