[2022-11-22T01:12:50.049+0000] {taskinstance.py:1165} INFO - Dependencies all met for <TaskInstance: PG_to_S3.PG_to_S3 manual__2022-11-21T21:26:12.692587+00:00 [queued]>
[2022-11-22T01:12:50.064+0000] {taskinstance.py:1165} INFO - Dependencies all met for <TaskInstance: PG_to_S3.PG_to_S3 manual__2022-11-21T21:26:12.692587+00:00 [queued]>
[2022-11-22T01:12:50.066+0000] {taskinstance.py:1362} INFO - 
--------------------------------------------------------------------------------
[2022-11-22T01:12:50.070+0000] {taskinstance.py:1363} INFO - Starting attempt 67 of 67
[2022-11-22T01:12:50.074+0000] {taskinstance.py:1364} INFO - 
--------------------------------------------------------------------------------
[2022-11-22T01:12:50.091+0000] {taskinstance.py:1383} INFO - Executing <Task(PostgresToS3Operator): PG_to_S3> on 2022-11-21 21:26:12.692587+00:00
[2022-11-22T01:12:50.103+0000] {standard_task_runner.py:55} INFO - Started process 28488 to run task
[2022-11-22T01:12:50.113+0000] {standard_task_runner.py:82} INFO - Running: ['***', 'tasks', 'run', 'PG_to_S3', 'PG_to_S3', 'manual__2022-11-21T21:26:12.692587+00:00', '--job-id', '181', '--raw', '--subdir', 'DAGS_FOLDER/PGtoS3.py', '--cfg-path', '/tmp/tmp3ttbazh2']
[2022-11-22T01:12:50.122+0000] {standard_task_runner.py:83} INFO - Job 181: Subtask PG_to_S3
[2022-11-22T01:12:50.281+0000] {task_command.py:376} INFO - Running <TaskInstance: PG_to_S3.PG_to_S3 manual__2022-11-21T21:26:12.692587+00:00 [running]> on host b785e9657fa7
[2022-11-22T01:12:50.398+0000] {taskinstance.py:1592} INFO - Exporting the following env vars:
AIRFLOW_CTX_DAG_OWNER=eugeny
AIRFLOW_CTX_DAG_ID=PG_to_S3
AIRFLOW_CTX_TASK_ID=PG_to_S3
AIRFLOW_CTX_EXECUTION_DATE=2022-11-21T21:26:12.692587+00:00
AIRFLOW_CTX_TRY_NUMBER=67
AIRFLOW_CTX_DAG_RUN_ID=manual__2022-11-21T21:26:12.692587+00:00
[2022-11-22T01:12:52.126+0000] {taskinstance.py:1851} ERROR - Task failed with exception
Traceback (most recent call last):
  File "/opt/airflow/plugins/operators/pgtos3.py", line 30, in execute
    self.s3().Bucket(self.bucket).upload_file(self.filename, self.postgres())
  File "/opt/airflow/plugins/operators/pgtos3.py", line 52, in postgres
    return(results)
NameError: name 'results' is not defined
[2022-11-22T01:12:52.156+0000] {taskinstance.py:1406} INFO - Marking task as FAILED. dag_id=PG_to_S3, task_id=PG_to_S3, execution_date=20221121T212612, start_date=20221122T011250, end_date=20221122T011252
[2022-11-22T01:12:52.172+0000] {standard_task_runner.py:105} ERROR - Failed to execute job 181 for task PG_to_S3 (name 'results' is not defined; 28488)
[2022-11-22T01:12:52.219+0000] {local_task_job.py:164} INFO - Task exited with return code 1
[2022-11-22T01:12:52.237+0000] {local_task_job.py:273} INFO - 0 downstream tasks scheduled from follow-on schedule check
