[2022-11-22T00:07:58.324+0000] {taskinstance.py:1165} INFO - Dependencies all met for <TaskInstance: PG_to_S3.PG_to_S3 manual__2022-11-21T21:26:12.692587+00:00 [queued]>
[2022-11-22T00:07:58.334+0000] {taskinstance.py:1165} INFO - Dependencies all met for <TaskInstance: PG_to_S3.PG_to_S3 manual__2022-11-21T21:26:12.692587+00:00 [queued]>
[2022-11-22T00:07:58.336+0000] {taskinstance.py:1362} INFO - 
--------------------------------------------------------------------------------
[2022-11-22T00:07:58.338+0000] {taskinstance.py:1363} INFO - Starting attempt 46 of 46
[2022-11-22T00:07:58.340+0000] {taskinstance.py:1364} INFO - 
--------------------------------------------------------------------------------
[2022-11-22T00:07:58.351+0000] {taskinstance.py:1383} INFO - Executing <Task(PostgresToS3Operator): PG_to_S3> on 2022-11-21 21:26:12.692587+00:00
[2022-11-22T00:07:58.358+0000] {standard_task_runner.py:55} INFO - Started process 25362 to run task
[2022-11-22T00:07:58.363+0000] {standard_task_runner.py:82} INFO - Running: ['***', 'tasks', 'run', 'PG_to_S3', 'PG_to_S3', 'manual__2022-11-21T21:26:12.692587+00:00', '--job-id', '160', '--raw', '--subdir', 'DAGS_FOLDER/PGtoS3.py', '--cfg-path', '/tmp/tmp5zqmfl9k']
[2022-11-22T00:07:58.366+0000] {standard_task_runner.py:83} INFO - Job 160: Subtask PG_to_S3
[2022-11-22T00:07:58.451+0000] {task_command.py:376} INFO - Running <TaskInstance: PG_to_S3.PG_to_S3 manual__2022-11-21T21:26:12.692587+00:00 [running]> on host b785e9657fa7
[2022-11-22T00:07:58.508+0000] {taskinstance.py:1592} INFO - Exporting the following env vars:
AIRFLOW_CTX_DAG_OWNER=eugeny
AIRFLOW_CTX_DAG_ID=PG_to_S3
AIRFLOW_CTX_TASK_ID=PG_to_S3
AIRFLOW_CTX_EXECUTION_DATE=2022-11-21T21:26:12.692587+00:00
AIRFLOW_CTX_TRY_NUMBER=46
AIRFLOW_CTX_DAG_RUN_ID=manual__2022-11-21T21:26:12.692587+00:00
[2022-11-22T00:08:00.936+0000] {taskinstance.py:1851} ERROR - Task failed with exception
Traceback (most recent call last):
  File "/opt/airflow/plugins/operators/pgtos3.py", line 28, in execute
    self.s3().Bucket(self.bucket).upload_file(self.filename, self.postgres())
  File "/opt/airflow/plugins/operators/pgtos3.py", line 40, in postgres
    pg_hook = PostgresHook.get_hook(self.database)
  File "/home/airflow/.local/lib/python3.7/site-packages/airflow/hooks/base.py", line 84, in get_hook
    connection = cls.get_connection(conn_id)
  File "/home/airflow/.local/lib/python3.7/site-packages/airflow/hooks/base.py", line 70, in get_connection
    conn = Connection.get_connection_from_secrets(conn_id)
  File "/home/airflow/.local/lib/python3.7/site-packages/airflow/models/connection.py", line 432, in get_connection_from_secrets
    raise AirflowNotFoundException(f"The conn_id `{conn_id}` isn't defined")
airflow.exceptions.AirflowNotFoundException: The conn_id `aws` isn't defined
[2022-11-22T00:08:00.943+0000] {taskinstance.py:1406} INFO - Marking task as FAILED. dag_id=PG_to_S3, task_id=PG_to_S3, execution_date=20221121T212612, start_date=20221122T000758, end_date=20221122T000800
[2022-11-22T00:08:00.952+0000] {standard_task_runner.py:105} ERROR - Failed to execute job 160 for task PG_to_S3 (The conn_id `aws` isn't defined; 25362)
[2022-11-22T00:08:00.999+0000] {local_task_job.py:164} INFO - Task exited with return code 1
[2022-11-22T00:08:01.024+0000] {local_task_job.py:273} INFO - 0 downstream tasks scheduled from follow-on schedule check
