[2022-11-10T20:14:13.205+0000] {taskinstance.py:1165} INFO - Dependencies all met for <TaskInstance: a_third_dag.insert_table manual__2022-11-10T20:07:44.450017+00:00 [queued]>
[2022-11-10T20:14:13.232+0000] {taskinstance.py:1165} INFO - Dependencies all met for <TaskInstance: a_third_dag.insert_table manual__2022-11-10T20:07:44.450017+00:00 [queued]>
[2022-11-10T20:14:13.234+0000] {taskinstance.py:1362} INFO - 
--------------------------------------------------------------------------------
[2022-11-10T20:14:13.240+0000] {taskinstance.py:1363} INFO - Starting attempt 5 of 5
[2022-11-10T20:14:13.245+0000] {taskinstance.py:1364} INFO - 
--------------------------------------------------------------------------------
[2022-11-10T20:14:13.255+0000] {taskinstance.py:1383} INFO - Executing <Task(PostgresOperator): insert_table> on 2022-11-10 20:07:44.450017+00:00
[2022-11-10T20:14:13.261+0000] {standard_task_runner.py:55} INFO - Started process 16421 to run task
[2022-11-10T20:14:13.264+0000] {standard_task_runner.py:82} INFO - Running: ['***', 'tasks', 'run', 'a_third_dag', 'insert_table', 'manual__2022-11-10T20:07:44.450017+00:00', '--job-id', '65', '--raw', '--subdir', 'DAGS_FOLDER/third_dug.py', '--cfg-path', '/tmp/tmp9pb54jvm']
[2022-11-10T20:14:13.270+0000] {standard_task_runner.py:83} INFO - Job 65: Subtask insert_table
[2022-11-10T20:14:13.338+0000] {task_command.py:376} INFO - Running <TaskInstance: a_third_dag.insert_table manual__2022-11-10T20:07:44.450017+00:00 [running]> on host 0b03955da713
[2022-11-10T20:14:13.409+0000] {taskinstance.py:1592} INFO - Exporting the following env vars:
AIRFLOW_CTX_DAG_OWNER=***
AIRFLOW_CTX_DAG_ID=a_third_dag
AIRFLOW_CTX_TASK_ID=insert_table
AIRFLOW_CTX_EXECUTION_DATE=2022-11-10T20:07:44.450017+00:00
AIRFLOW_CTX_TRY_NUMBER=5
AIRFLOW_CTX_DAG_RUN_ID=manual__2022-11-10T20:07:44.450017+00:00
[2022-11-10T20:14:13.424+0000] {base.py:71} INFO - Using connection ID '***' for task execution.
[2022-11-10T20:14:13.436+0000] {sql.py:315} INFO - Running statement: 
             INSERT INTO currency_pair_6 (date_scrapping, price, pair)
             VALUES (default, 1234, pair)
             ;
           , parameters: None
[2022-11-10T20:14:13.438+0000] {taskinstance.py:1851} ERROR - Task failed with exception
Traceback (most recent call last):
  File "/home/airflow/.local/lib/python3.7/site-packages/airflow/providers/postgres/operators/postgres.py", line 94, in execute
    self.hook.run(self.sql, self.autocommit, parameters=self.parameters)
  File "/home/airflow/.local/lib/python3.7/site-packages/airflow/providers/common/sql/hooks/sql.py", line 295, in run
    self._run_command(cur, sql_statement, parameters)
  File "/home/airflow/.local/lib/python3.7/site-packages/airflow/providers/common/sql/hooks/sql.py", line 320, in _run_command
    cur.execute(sql_statement)
psycopg2.errors.UndefinedColumn: column "pair" does not exist
LINE 3:              VALUES (default, 1234, pair)
                                            ^
HINT:  There is a column named "pair" in table "currency_pair_6", but it cannot be referenced from this part of the query.

[2022-11-10T20:14:13.463+0000] {taskinstance.py:1406} INFO - Marking task as FAILED. dag_id=a_third_dag, task_id=insert_table, execution_date=20221110T200744, start_date=20221110T201413, end_date=20221110T201413
[2022-11-10T20:14:13.475+0000] {standard_task_runner.py:105} ERROR - Failed to execute job 65 for task insert_table (column "pair" does not exist
LINE 3:              VALUES (default, 1234, pair)
                                            ^
HINT:  There is a column named "pair" in table "currency_pair_6", but it cannot be referenced from this part of the query.
; 16421)
[2022-11-10T20:14:13.526+0000] {local_task_job.py:164} INFO - Task exited with return code 1
[2022-11-10T20:14:13.549+0000] {local_task_job.py:273} INFO - 0 downstream tasks scheduled from follow-on schedule check
