[2022-11-26T00:21:01.987+0000] {taskinstance.py:1165} INFO - Dependencies all met for <TaskInstance: PG_to_S3.PG_to_S3 scheduled__2022-11-25T00:00:00+00:00 [queued]>
[2022-11-26T00:21:02.040+0000] {taskinstance.py:1165} INFO - Dependencies all met for <TaskInstance: PG_to_S3.PG_to_S3 scheduled__2022-11-25T00:00:00+00:00 [queued]>
[2022-11-26T00:21:02.048+0000] {taskinstance.py:1362} INFO - 
--------------------------------------------------------------------------------
[2022-11-26T00:21:02.058+0000] {taskinstance.py:1363} INFO - Starting attempt 1 of 1
[2022-11-26T00:21:02.063+0000] {taskinstance.py:1364} INFO - 
--------------------------------------------------------------------------------
[2022-11-26T00:21:02.164+0000] {taskinstance.py:1383} INFO - Executing <Task(PostgresToS3Operator): PG_to_S3> on 2022-11-25 00:00:00+00:00
[2022-11-26T00:21:02.219+0000] {standard_task_runner.py:55} INFO - Started process 77957 to run task
[2022-11-26T00:21:02.246+0000] {standard_task_runner.py:82} INFO - Running: ['***', 'tasks', 'run', 'PG_to_S3', 'PG_to_S3', 'scheduled__2022-11-25T00:00:00+00:00', '--job-id', '239', '--raw', '--subdir', 'DAGS_FOLDER/PGtoS3.py', '--cfg-path', '/tmp/tmp15s1ty89']
[2022-11-26T00:21:02.279+0000] {standard_task_runner.py:83} INFO - Job 239: Subtask PG_to_S3
[2022-11-26T00:21:02.906+0000] {task_command.py:376} INFO - Running <TaskInstance: PG_to_S3.PG_to_S3 scheduled__2022-11-25T00:00:00+00:00 [running]> on host b785e9657fa7
[2022-11-26T00:21:03.278+0000] {taskinstance.py:1592} INFO - Exporting the following env vars:
AIRFLOW_CTX_DAG_OWNER=eugeny
AIRFLOW_CTX_DAG_ID=PG_to_S3
AIRFLOW_CTX_TASK_ID=PG_to_S3
AIRFLOW_CTX_EXECUTION_DATE=2022-11-25T00:00:00+00:00
AIRFLOW_CTX_TRY_NUMBER=1
AIRFLOW_CTX_DAG_RUN_ID=scheduled__2022-11-25T00:00:00+00:00
[2022-11-26T00:21:25.865+0000] {taskinstance.py:1851} ERROR - Task failed with exception
Traceback (most recent call last):
  File "/opt/airflow/plugins/operators/pgtos3.py", line 33, in execute
    self.s3()
  File "/opt/airflow/plugins/operators/pgtos3.py", line 60, in s3
    return object.put(Body=data)
  File "/home/airflow/.local/lib/python3.7/site-packages/boto3/resources/factory.py", line 580, in do_action
    response = action(self, *args, **kwargs)
  File "/home/airflow/.local/lib/python3.7/site-packages/boto3/resources/action.py", line 88, in __call__
    response = getattr(parent.meta.client, operation_name)(*args, **params)
  File "/home/airflow/.local/lib/python3.7/site-packages/botocore/client.py", line 514, in _api_call
    return self._make_api_call(operation_name, kwargs)
  File "/home/airflow/.local/lib/python3.7/site-packages/botocore/client.py", line 938, in _make_api_call
    raise error_class(parsed_response, operation_name)
botocore.exceptions.ClientError: An error occurred (RequestTimeTooSkewed) when calling the PutObject operation: The difference between the request time and the current time is too large.
[2022-11-26T00:21:25.932+0000] {taskinstance.py:1406} INFO - Marking task as FAILED. dag_id=PG_to_S3, task_id=PG_to_S3, execution_date=20221125T000000, start_date=20221126T002102, end_date=20221126T002125
[2022-11-26T00:21:26.010+0000] {standard_task_runner.py:105} ERROR - Failed to execute job 239 for task PG_to_S3 (An error occurred (RequestTimeTooSkewed) when calling the PutObject operation: The difference between the request time and the current time is too large.; 77957)
[2022-11-26T00:21:26.219+0000] {local_task_job.py:164} INFO - Task exited with return code 1
[2022-11-26T00:21:26.260+0000] {local_task_job.py:273} INFO - 0 downstream tasks scheduled from follow-on schedule check
